dict_keys(['Meta Data', 'Time Series (5min)'])
1170
dict_keys(['Meta Data', 'Time Series (5min)'])
1170
dict_keys(['Meta Data', 'Time Series (5min)'])
1166
dict_keys(['Meta Data', 'Time Series (5min)'])
1165
dict_keys(['Meta Data', 'Time Series (5min)'])
1165
dict_keys(['Meta Data', 'Time Series (5min)'])
1170
dict_keys(['Meta Data', 'Time Series (5min)'])
1170
dict_keys(['Meta Data', 'Time Series (5min)'])
14
Traceback (most recent call last):
  File "/home/sergio/github/algotrader/Datagraber.py", line 110, in <module>
    with open('~/github/algotrader/sdata.pkl','rb') as f:
FileNotFoundError: [Errno 2] No such file or directory: '~/github/algotrader/sdata.pkl'
dict_keys(['Meta Data', 'Time Series (5min)'])
1170
dict_keys(['Meta Data', 'Time Series (5min)'])
1170
dict_keys(['Meta Data', 'Time Series (5min)'])
1165
dict_keys(['Meta Data', 'Time Series (5min)'])
1166
dict_keys(['Meta Data', 'Time Series (5min)'])
1166
dict_keys(['Meta Data', 'Time Series (5min)'])
1170
dict_keys(['Meta Data', 'Time Series (5min)'])
1170
dict_keys(['Meta Data', 'Time Series (5min)'])
14
dict_keys(['Meta Data', 'Time Series (5min)'])
1170
dict_keys(['Meta Data', 'Time Series (5min)'])
1170
dict_keys(['Meta Data', 'Time Series (5min)'])
1165
dict_keys(['Meta Data', 'Time Series (5min)'])
1165
dict_keys(['Meta Data', 'Time Series (5min)'])
1166
dict_keys(['Meta Data', 'Time Series (5min)'])
1170
dict_keys(['Meta Data', 'Time Series (5min)'])
1170
dict_keys(['Meta Data', 'Time Series (5min)'])
14
dict_keys(['Meta Data', 'Time Series (5min)'])
1100
dict_keys(['Meta Data', 'Time Series (5min)'])
1100
dict_keys(['Meta Data', 'Time Series (5min)'])
1096
dict_keys(['Meta Data', 'Time Series (5min)'])
1096
dict_keys(['Meta Data', 'Time Series (5min)'])
1095
dict_keys(['Meta Data', 'Time Series (5min)'])
1100
dict_keys(['Meta Data', 'Time Series (5min)'])
1100
dict_keys(['Meta Data', 'Time Series (5min)'])
14
dict_keys(['Meta Data', 'Time Series (5min)'])
1093
dict_keys(['Meta Data', 'Time Series (5min)'])
1093
dict_keys(['Meta Data', 'Time Series (5min)'])
1088
dict_keys(['Meta Data', 'Time Series (5min)'])
1088
dict_keys(['Meta Data', 'Time Series (5min)'])
1089
dict_keys(['Meta Data', 'Time Series (5min)'])
1093
dict_keys(['Meta Data', 'Time Series (5min)'])
1094
dict_keys(['Meta Data', 'Time Series (5min)'])
13
dict_keys(['Meta Data', 'Time Series (5min)'])
{'Note': 'Thank you for using Alpha Vantage! Our standard API call frequency is 5 calls per minute and 500 calls per day. Please visit https://www.alphavantage.co/premium/ if you would like to target a higher API call frequency.'}
1107
Traceback (most recent call last):
  File "/home/sergio/github/algotrader/Datagraber.py", line 117, in <module>
    [x.update(ohlcurl+x.tick,macdurl+x.tick,'5min') for x in symbolsdata]
  File "/home/sergio/github/algotrader/Datagraber.py", line 117, in <listcomp>
    [x.update(ohlcurl+x.tick,macdurl+x.tick,'5min') for x in symbolsdata]
  File "/home/sergio/github/algotrader/Datagraber.py", line 85, in update
    for keyo,keym in zip(list(ohlcdata.keys()),list(macddata.keys())):
UnboundLocalError: local variable 'macddata' referenced before assignment
dict_keys(['Meta Data', 'Time Series (5min)'])
1107
dict_keys(['Meta Data', 'Time Series (5min)'])
1107
dict_keys(['Meta Data', 'Time Series (5min)'])
1104
dict_keys(['Meta Data', 'Time Series (5min)'])
1104
dict_keys(['Meta Data', 'Time Series (5min)'])
1103
dict_keys(['Meta Data', 'Time Series (5min)'])
1108
dict_keys(['Meta Data', 'Time Series (5min)'])
1108
dict_keys(['Meta Data', 'Time Series (5min)'])
13
dict_keys(['Meta Data', 'Time Series (5min)'])
1108
dict_keys(['Meta Data', 'Time Series (5min)'])
1109
dict_keys(['Meta Data', 'Time Series (5min)'])
1104
dict_keys(['Meta Data', 'Time Series (5min)'])
1104
dict_keys(['Meta Data', 'Time Series (5min)'])
1105
dict_keys(['Meta Data', 'Time Series (5min)'])
1109
dict_keys(['Meta Data', 'Time Series (5min)'])
1109
dict_keys(['Meta Data', 'Time Series (5min)'])
13
dict_keys(['Meta Data', 'Time Series (5min)'])
1170
dict_keys(['Meta Data', 'Time Series (5min)'])
1170
dict_keys(['Meta Data', 'Time Series (5min)'])
1161
dict_keys(['Meta Data', 'Time Series (5min)'])
1158
dict_keys(['Meta Data', 'Time Series (5min)'])
1161
dict_keys(['Meta Data', 'Time Series (5min)'])
1170
dict_keys(['Meta Data', 'Time Series (5min)'])
1170
dict_keys(['Meta Data', 'Time Series (5min)'])
14
Traceback (most recent call last):
  File "/home/sergio/anaconda3/lib/python3.7/site-packages/urllib3/connection.py", line 157, in _new_conn
    (self._dns_host, self.port), self.timeout, **extra_kw
  File "/home/sergio/anaconda3/lib/python3.7/site-packages/urllib3/util/connection.py", line 61, in create_connection
    for res in socket.getaddrinfo(host, port, family, socket.SOCK_STREAM):
  File "/home/sergio/anaconda3/lib/python3.7/socket.py", line 748, in getaddrinfo
    for res in _socket.getaddrinfo(host, port, family, type, proto, flags):
socket.gaierror: [Errno -3] Temporary failure in name resolution

During handling of the above exception, another exception occurred:

Traceback (most recent call last):
  File "/home/sergio/anaconda3/lib/python3.7/site-packages/urllib3/connectionpool.py", line 672, in urlopen
    chunked=chunked,
  File "/home/sergio/anaconda3/lib/python3.7/site-packages/urllib3/connectionpool.py", line 376, in _make_request
    self._validate_conn(conn)
  File "/home/sergio/anaconda3/lib/python3.7/site-packages/urllib3/connectionpool.py", line 994, in _validate_conn
    conn.connect()
  File "/home/sergio/anaconda3/lib/python3.7/site-packages/urllib3/connection.py", line 300, in connect
    conn = self._new_conn()
  File "/home/sergio/anaconda3/lib/python3.7/site-packages/urllib3/connection.py", line 169, in _new_conn
    self, "Failed to establish a new connection: %s" % e
urllib3.exceptions.NewConnectionError: <urllib3.connection.VerifiedHTTPSConnection object at 0x7f8f43d74690>: Failed to establish a new connection: [Errno -3] Temporary failure in name resolution

During handling of the above exception, another exception occurred:

Traceback (most recent call last):
  File "/home/sergio/github/algotrader/Datagraber.py", line 117, in <module>
    [x.update(ohlcurl+x.tick,macdurl+x.tick,'5min') for x in symbolsdata]
  File "/home/sergio/github/algotrader/Datagraber.py", line 117, in <listcomp>
    [x.update(ohlcurl+x.tick,macdurl+x.tick,'5min') for x in symbolsdata]
  File "/home/sergio/github/algotrader/Datagraber.py", line 74, in update
    ohlctmp=json.loads(http.request('GET', ohlcurl).data)
  File "/home/sergio/anaconda3/lib/python3.7/site-packages/urllib3/request.py", line 76, in request
    method, url, fields=fields, headers=headers, **urlopen_kw
  File "/home/sergio/anaconda3/lib/python3.7/site-packages/urllib3/request.py", line 97, in request_encode_url
    return self.urlopen(method, url, **extra_kw)
  File "/home/sergio/anaconda3/lib/python3.7/site-packages/urllib3/poolmanager.py", line 330, in urlopen
    response = conn.urlopen(method, u.request_uri, **kw)
  File "/home/sergio/anaconda3/lib/python3.7/site-packages/urllib3/connectionpool.py", line 760, in urlopen
    **response_kw
  File "/home/sergio/anaconda3/lib/python3.7/site-packages/urllib3/connectionpool.py", line 760, in urlopen
    **response_kw
  File "/home/sergio/anaconda3/lib/python3.7/site-packages/urllib3/connectionpool.py", line 760, in urlopen
    **response_kw
  File "/home/sergio/anaconda3/lib/python3.7/site-packages/urllib3/connectionpool.py", line 720, in urlopen
    method, url, error=e, _pool=self, _stacktrace=sys.exc_info()[2]
  File "/home/sergio/anaconda3/lib/python3.7/site-packages/urllib3/util/retry.py", line 436, in increment
    raise MaxRetryError(_pool, url, error or ResponseError(cause))
urllib3.exceptions.MaxRetryError: HTTPSConnectionPool(host='www.alphavantage.co', port=443): Max retries exceeded with url: /query?function=TIME_SERIES_INTRADAY&interval=5min&apikey=46O5MSJ0J745T9J8&outputsize=full&symbol=TSLA (Caused by NewConnectionError('<urllib3.connection.VerifiedHTTPSConnection object at 0x7f8f43d74690>: Failed to establish a new connection: [Errno -3] Temporary failure in name resolution'))
dict_keys(['Meta Data', 'Time Series (5min)'])
1170
dict_keys(['Meta Data', 'Time Series (5min)'])
1170
dict_keys(['Meta Data', 'Time Series (5min)'])
1158
dict_keys(['Meta Data', 'Time Series (5min)'])
1158
dict_keys(['Meta Data', 'Time Series (5min)'])
1158
dict_keys(['Meta Data', 'Time Series (5min)'])
1170
dict_keys(['Meta Data', 'Time Series (5min)'])
1170
dict_keys(['Meta Data', 'Time Series (5min)'])
14
dict_keys(['Meta Data', 'Time Series (5min)'])
1170
dict_keys(['Meta Data', 'Time Series (5min)'])
1170
dict_keys(['Meta Data', 'Time Series (5min)'])
1161
dict_keys(['Meta Data', 'Time Series (5min)'])
1158
dict_keys(['Meta Data', 'Time Series (5min)'])
1158
dict_keys(['Meta Data', 'Time Series (5min)'])
1170
dict_keys(['Meta Data', 'Time Series (5min)'])
1170
dict_keys(['Meta Data', 'Time Series (5min)'])
14
dict_keys(['Meta Data', 'Time Series (5min)'])
1170
dict_keys(['Meta Data', 'Time Series (5min)'])
1170
dict_keys(['Meta Data', 'Time Series (5min)'])
1161
dict_keys(['Meta Data', 'Time Series (5min)'])
1158
dict_keys(['Meta Data', 'Time Series (5min)'])
1161
dict_keys(['Meta Data', 'Time Series (5min)'])
1170
dict_keys(['Meta Data', 'Time Series (5min)'])
1170
dict_keys(['Meta Data', 'Time Series (5min)'])
14
dict_keys(['Meta Data', 'Time Series (5min)'])
1170
dict_keys(['Meta Data', 'Time Series (5min)'])
1170
dict_keys(['Meta Data', 'Time Series (5min)'])
1161
dict_keys(['Meta Data', 'Time Series (5min)'])
1161
dict_keys(['Meta Data', 'Time Series (5min)'])
1161
dict_keys(['Meta Data', 'Time Series (5min)'])
1170
dict_keys(['Meta Data', 'Time Series (5min)'])
1170
dict_keys(['Meta Data', 'Time Series (5min)'])
14
Traceback (most recent call last):
  File "/home/sergio/anaconda3/lib/python3.7/site-packages/urllib3/connection.py", line 157, in _new_conn
    (self._dns_host, self.port), self.timeout, **extra_kw
  File "/home/sergio/anaconda3/lib/python3.7/site-packages/urllib3/util/connection.py", line 61, in create_connection
    for res in socket.getaddrinfo(host, port, family, socket.SOCK_STREAM):
  File "/home/sergio/anaconda3/lib/python3.7/socket.py", line 748, in getaddrinfo
    for res in _socket.getaddrinfo(host, port, family, type, proto, flags):
socket.gaierror: [Errno -3] Temporary failure in name resolution

During handling of the above exception, another exception occurred:

Traceback (most recent call last):
  File "/home/sergio/anaconda3/lib/python3.7/site-packages/urllib3/connectionpool.py", line 672, in urlopen
    chunked=chunked,
  File "/home/sergio/anaconda3/lib/python3.7/site-packages/urllib3/connectionpool.py", line 376, in _make_request
    self._validate_conn(conn)
  File "/home/sergio/anaconda3/lib/python3.7/site-packages/urllib3/connectionpool.py", line 994, in _validate_conn
    conn.connect()
  File "/home/sergio/anaconda3/lib/python3.7/site-packages/urllib3/connection.py", line 300, in connect
    conn = self._new_conn()
  File "/home/sergio/anaconda3/lib/python3.7/site-packages/urllib3/connection.py", line 169, in _new_conn
    self, "Failed to establish a new connection: %s" % e
urllib3.exceptions.NewConnectionError: <urllib3.connection.VerifiedHTTPSConnection object at 0x7fefab603950>: Failed to establish a new connection: [Errno -3] Temporary failure in name resolution

During handling of the above exception, another exception occurred:

Traceback (most recent call last):
  File "/home/sergio/github/algotrader/Datagraber.py", line 117, in <module>
    [x.update(ohlcurl+x.tick,macdurl+x.tick,'5min') for x in symbolsdata]
  File "/home/sergio/github/algotrader/Datagraber.py", line 117, in <listcomp>
    [x.update(ohlcurl+x.tick,macdurl+x.tick,'5min') for x in symbolsdata]
  File "/home/sergio/github/algotrader/Datagraber.py", line 74, in update
    ohlctmp=json.loads(http.request('GET', ohlcurl).data)
  File "/home/sergio/anaconda3/lib/python3.7/site-packages/urllib3/request.py", line 76, in request
    method, url, fields=fields, headers=headers, **urlopen_kw
  File "/home/sergio/anaconda3/lib/python3.7/site-packages/urllib3/request.py", line 97, in request_encode_url
    return self.urlopen(method, url, **extra_kw)
  File "/home/sergio/anaconda3/lib/python3.7/site-packages/urllib3/poolmanager.py", line 330, in urlopen
    response = conn.urlopen(method, u.request_uri, **kw)
  File "/home/sergio/anaconda3/lib/python3.7/site-packages/urllib3/connectionpool.py", line 760, in urlopen
    **response_kw
  File "/home/sergio/anaconda3/lib/python3.7/site-packages/urllib3/connectionpool.py", line 760, in urlopen
    **response_kw
  File "/home/sergio/anaconda3/lib/python3.7/site-packages/urllib3/connectionpool.py", line 760, in urlopen
    **response_kw
  File "/home/sergio/anaconda3/lib/python3.7/site-packages/urllib3/connectionpool.py", line 720, in urlopen
    method, url, error=e, _pool=self, _stacktrace=sys.exc_info()[2]
  File "/home/sergio/anaconda3/lib/python3.7/site-packages/urllib3/util/retry.py", line 436, in increment
    raise MaxRetryError(_pool, url, error or ResponseError(cause))
urllib3.exceptions.MaxRetryError: HTTPSConnectionPool(host='www.alphavantage.co', port=443): Max retries exceeded with url: /query?function=TIME_SERIES_INTRADAY&interval=5min&apikey=46O5MSJ0J745T9J8&outputsize=full&symbol=TSLA (Caused by NewConnectionError('<urllib3.connection.VerifiedHTTPSConnection object at 0x7fefab603950>: Failed to establish a new connection: [Errno -3] Temporary failure in name resolution'))
dict_keys(['Meta Data', 'Time Series (5min)'])
1136
dict_keys(['Meta Data', 'Time Series (5min)'])
1137
dict_keys(['Meta Data', 'Time Series (5min)'])
1133
dict_keys(['Meta Data', 'Time Series (5min)'])
1133
dict_keys(['Meta Data', 'Time Series (5min)'])
{'Note': 'Thank you for using Alpha Vantage! Our standard API call frequency is 5 calls per minute and 500 calls per day. Please visit https://www.alphavantage.co/premium/ if you would like to target a higher API call frequency.'}
1129
Traceback (most recent call last):
  File "/home/sergio/github/algotrader/Datagraber.py", line 117, in <module>
    [x.update(ohlcurl+x.tick,macdurl+x.tick,'5min') for x in symbolsdata]
  File "/home/sergio/github/algotrader/Datagraber.py", line 117, in <listcomp>
    [x.update(ohlcurl+x.tick,macdurl+x.tick,'5min') for x in symbolsdata]
  File "/home/sergio/github/algotrader/Datagraber.py", line 85, in update
    for keyo,keym in zip(list(ohlcdata.keys()),list(macddata.keys())):
UnboundLocalError: local variable 'macddata' referenced before assignment
dict_keys(['Meta Data', 'Time Series (5min)'])
1137
dict_keys(['Note'])
Traceback (most recent call last):
  File "/home/sergio/github/algotrader/Datagraber.py", line 117, in <module>
    [x.update(ohlcurl+x.tick,macdurl+x.tick,'5min') for x in symbolsdata]
  File "/home/sergio/github/algotrader/Datagraber.py", line 117, in <listcomp>
    [x.update(ohlcurl+x.tick,macdurl+x.tick,'5min') for x in symbolsdata]
  File "/home/sergio/github/algotrader/Datagraber.py", line 76, in update
    ohlcdata=ohlctmp['Time Series ('+interval+')']
KeyError: 'Time Series (5min)'
dict_keys(['Meta Data', 'Time Series (5min)'])
1151
dict_keys(['Meta Data', 'Time Series (5min)'])
1151
dict_keys(['Meta Data', 'Time Series (5min)'])
1147
dict_keys(['Meta Data', 'Time Series (5min)'])
1147
dict_keys(['Meta Data', 'Time Series (5min)'])
1143
dict_keys(['Meta Data', 'Time Series (5min)'])
1151
dict_keys(['Meta Data', 'Time Series (5min)'])
1151
dict_keys(['Meta Data', 'Time Series (5min)'])
14
dict_keys(['Meta Data', 'Time Series (5min)'])
1156
dict_keys(['Note'])
Traceback (most recent call last):
  File "/home/sergio/github/algotrader/Datagraber.py", line 117, in <module>
    [x.update(ohlcurl+x.tick,macdurl+x.tick,'5min') for x in symbolsdata]
  File "/home/sergio/github/algotrader/Datagraber.py", line 117, in <listcomp>
    [x.update(ohlcurl+x.tick,macdurl+x.tick,'5min') for x in symbolsdata]
  File "/home/sergio/github/algotrader/Datagraber.py", line 76, in update
    ohlcdata=ohlctmp['Time Series ('+interval+')']
KeyError: 'Time Series (5min)'
dict_keys(['Meta Data', 'Time Series (5min)'])
1155
dict_keys(['Meta Data', 'Time Series (5min)'])
1156
dict_keys(['Meta Data', 'Time Series (5min)'])
1148
dict_keys(['Meta Data', 'Time Series (5min)'])
1148
dict_keys(['Meta Data', 'Time Series (5min)'])
1148
dict_keys(['Meta Data', 'Time Series (5min)'])
1156
dict_keys(['Meta Data', 'Time Series (5min)'])
{'Note': 'Thank you for using Alpha Vantage! Our standard API call frequency is 5 calls per minute and 500 calls per day. Please visit https://www.alphavantage.co/premium/ if you would like to target a higher API call frequency.'}
1156
Traceback (most recent call last):
  File "/home/sergio/github/algotrader/Datagraber.py", line 117, in <module>
    [x.update(ohlcurl+x.tick,macdurl+x.tick,'5min') for x in symbolsdata]
  File "/home/sergio/github/algotrader/Datagraber.py", line 117, in <listcomp>
    [x.update(ohlcurl+x.tick,macdurl+x.tick,'5min') for x in symbolsdata]
  File "/home/sergio/github/algotrader/Datagraber.py", line 85, in update
    for keyo,keym in zip(list(ohlcdata.keys()),list(macddata.keys())):
UnboundLocalError: local variable 'macddata' referenced before assignment
Traceback (most recent call last):
  File "/home/sergio/anaconda3/lib/python3.7/site-packages/urllib3/connection.py", line 157, in _new_conn
    (self._dns_host, self.port), self.timeout, **extra_kw
  File "/home/sergio/anaconda3/lib/python3.7/site-packages/urllib3/util/connection.py", line 61, in create_connection
    for res in socket.getaddrinfo(host, port, family, socket.SOCK_STREAM):
  File "/home/sergio/anaconda3/lib/python3.7/socket.py", line 748, in getaddrinfo
    for res in _socket.getaddrinfo(host, port, family, type, proto, flags):
socket.gaierror: [Errno -3] Temporary failure in name resolution

During handling of the above exception, another exception occurred:

Traceback (most recent call last):
  File "/home/sergio/anaconda3/lib/python3.7/site-packages/urllib3/connectionpool.py", line 672, in urlopen
    chunked=chunked,
  File "/home/sergio/anaconda3/lib/python3.7/site-packages/urllib3/connectionpool.py", line 376, in _make_request
    self._validate_conn(conn)
  File "/home/sergio/anaconda3/lib/python3.7/site-packages/urllib3/connectionpool.py", line 994, in _validate_conn
    conn.connect()
  File "/home/sergio/anaconda3/lib/python3.7/site-packages/urllib3/connection.py", line 300, in connect
    conn = self._new_conn()
  File "/home/sergio/anaconda3/lib/python3.7/site-packages/urllib3/connection.py", line 169, in _new_conn
    self, "Failed to establish a new connection: %s" % e
urllib3.exceptions.NewConnectionError: <urllib3.connection.VerifiedHTTPSConnection object at 0x7fdfd877e990>: Failed to establish a new connection: [Errno -3] Temporary failure in name resolution

During handling of the above exception, another exception occurred:

Traceback (most recent call last):
  File "/home/sergio/github/algotrader/Datagraber.py", line 117, in <module>
    [x.update(ohlcurl+x.tick,macdurl+x.tick,'5min') for x in symbolsdata]
  File "/home/sergio/github/algotrader/Datagraber.py", line 117, in <listcomp>
    [x.update(ohlcurl+x.tick,macdurl+x.tick,'5min') for x in symbolsdata]
  File "/home/sergio/github/algotrader/Datagraber.py", line 74, in update
    ohlctmp=json.loads(http.request('GET', ohlcurl).data)
  File "/home/sergio/anaconda3/lib/python3.7/site-packages/urllib3/request.py", line 76, in request
    method, url, fields=fields, headers=headers, **urlopen_kw
  File "/home/sergio/anaconda3/lib/python3.7/site-packages/urllib3/request.py", line 97, in request_encode_url
    return self.urlopen(method, url, **extra_kw)
  File "/home/sergio/anaconda3/lib/python3.7/site-packages/urllib3/poolmanager.py", line 330, in urlopen
    response = conn.urlopen(method, u.request_uri, **kw)
  File "/home/sergio/anaconda3/lib/python3.7/site-packages/urllib3/connectionpool.py", line 760, in urlopen
    **response_kw
  File "/home/sergio/anaconda3/lib/python3.7/site-packages/urllib3/connectionpool.py", line 760, in urlopen
    **response_kw
  File "/home/sergio/anaconda3/lib/python3.7/site-packages/urllib3/connectionpool.py", line 760, in urlopen
    **response_kw
  File "/home/sergio/anaconda3/lib/python3.7/site-packages/urllib3/connectionpool.py", line 720, in urlopen
    method, url, error=e, _pool=self, _stacktrace=sys.exc_info()[2]
  File "/home/sergio/anaconda3/lib/python3.7/site-packages/urllib3/util/retry.py", line 436, in increment
    raise MaxRetryError(_pool, url, error or ResponseError(cause))
urllib3.exceptions.MaxRetryError: HTTPSConnectionPool(host='www.alphavantage.co', port=443): Max retries exceeded with url: /query?function=TIME_SERIES_INTRADAY&interval=5min&apikey=46O5MSJ0J745T9J8&outputsize=full&symbol=TSLA (Caused by NewConnectionError('<urllib3.connection.VerifiedHTTPSConnection object at 0x7fdfd877e990>: Failed to establish a new connection: [Errno -3] Temporary failure in name resolution'))
Traceback (most recent call last):
  File "/home/sergio/anaconda3/lib/python3.7/site-packages/urllib3/connection.py", line 157, in _new_conn
    (self._dns_host, self.port), self.timeout, **extra_kw
  File "/home/sergio/anaconda3/lib/python3.7/site-packages/urllib3/util/connection.py", line 61, in create_connection
    for res in socket.getaddrinfo(host, port, family, socket.SOCK_STREAM):
  File "/home/sergio/anaconda3/lib/python3.7/socket.py", line 748, in getaddrinfo
    for res in _socket.getaddrinfo(host, port, family, type, proto, flags):
socket.gaierror: [Errno -3] Temporary failure in name resolution

During handling of the above exception, another exception occurred:

Traceback (most recent call last):
  File "/home/sergio/anaconda3/lib/python3.7/site-packages/urllib3/connectionpool.py", line 672, in urlopen
    chunked=chunked,
  File "/home/sergio/anaconda3/lib/python3.7/site-packages/urllib3/connectionpool.py", line 376, in _make_request
    self._validate_conn(conn)
  File "/home/sergio/anaconda3/lib/python3.7/site-packages/urllib3/connectionpool.py", line 994, in _validate_conn
    conn.connect()
  File "/home/sergio/anaconda3/lib/python3.7/site-packages/urllib3/connection.py", line 300, in connect
    conn = self._new_conn()
  File "/home/sergio/anaconda3/lib/python3.7/site-packages/urllib3/connection.py", line 169, in _new_conn
    self, "Failed to establish a new connection: %s" % e
urllib3.exceptions.NewConnectionError: <urllib3.connection.VerifiedHTTPSConnection object at 0x7f4ce754ba10>: Failed to establish a new connection: [Errno -3] Temporary failure in name resolution

During handling of the above exception, another exception occurred:

Traceback (most recent call last):
  File "/home/sergio/github/algotrader/Datagraber.py", line 117, in <module>
    [x.update(ohlcurl+x.tick,macdurl+x.tick,'5min') for x in symbolsdata]
  File "/home/sergio/github/algotrader/Datagraber.py", line 117, in <listcomp>
    [x.update(ohlcurl+x.tick,macdurl+x.tick,'5min') for x in symbolsdata]
  File "/home/sergio/github/algotrader/Datagraber.py", line 74, in update
    ohlctmp=json.loads(http.request('GET', ohlcurl).data)
  File "/home/sergio/anaconda3/lib/python3.7/site-packages/urllib3/request.py", line 76, in request
    method, url, fields=fields, headers=headers, **urlopen_kw
  File "/home/sergio/anaconda3/lib/python3.7/site-packages/urllib3/request.py", line 97, in request_encode_url
    return self.urlopen(method, url, **extra_kw)
  File "/home/sergio/anaconda3/lib/python3.7/site-packages/urllib3/poolmanager.py", line 330, in urlopen
    response = conn.urlopen(method, u.request_uri, **kw)
  File "/home/sergio/anaconda3/lib/python3.7/site-packages/urllib3/connectionpool.py", line 760, in urlopen
    **response_kw
  File "/home/sergio/anaconda3/lib/python3.7/site-packages/urllib3/connectionpool.py", line 760, in urlopen
    **response_kw
  File "/home/sergio/anaconda3/lib/python3.7/site-packages/urllib3/connectionpool.py", line 760, in urlopen
    **response_kw
  File "/home/sergio/anaconda3/lib/python3.7/site-packages/urllib3/connectionpool.py", line 720, in urlopen
    method, url, error=e, _pool=self, _stacktrace=sys.exc_info()[2]
  File "/home/sergio/anaconda3/lib/python3.7/site-packages/urllib3/util/retry.py", line 436, in increment
    raise MaxRetryError(_pool, url, error or ResponseError(cause))
urllib3.exceptions.MaxRetryError: HTTPSConnectionPool(host='www.alphavantage.co', port=443): Max retries exceeded with url: /query?function=TIME_SERIES_INTRADAY&interval=5min&apikey=46O5MSJ0J745T9J8&outputsize=full&symbol=TSLA (Caused by NewConnectionError('<urllib3.connection.VerifiedHTTPSConnection object at 0x7f4ce754ba10>: Failed to establish a new connection: [Errno -3] Temporary failure in name resolution'))
Traceback (most recent call last):
  File "/home/sergio/anaconda3/lib/python3.7/site-packages/urllib3/connection.py", line 157, in _new_conn
    (self._dns_host, self.port), self.timeout, **extra_kw
  File "/home/sergio/anaconda3/lib/python3.7/site-packages/urllib3/util/connection.py", line 61, in create_connection
    for res in socket.getaddrinfo(host, port, family, socket.SOCK_STREAM):
  File "/home/sergio/anaconda3/lib/python3.7/socket.py", line 748, in getaddrinfo
    for res in _socket.getaddrinfo(host, port, family, type, proto, flags):
socket.gaierror: [Errno -3] Temporary failure in name resolution

During handling of the above exception, another exception occurred:

Traceback (most recent call last):
  File "/home/sergio/anaconda3/lib/python3.7/site-packages/urllib3/connectionpool.py", line 672, in urlopen
    chunked=chunked,
  File "/home/sergio/anaconda3/lib/python3.7/site-packages/urllib3/connectionpool.py", line 376, in _make_request
    self._validate_conn(conn)
  File "/home/sergio/anaconda3/lib/python3.7/site-packages/urllib3/connectionpool.py", line 994, in _validate_conn
    conn.connect()
  File "/home/sergio/anaconda3/lib/python3.7/site-packages/urllib3/connection.py", line 300, in connect
    conn = self._new_conn()
  File "/home/sergio/anaconda3/lib/python3.7/site-packages/urllib3/connection.py", line 169, in _new_conn
    self, "Failed to establish a new connection: %s" % e
urllib3.exceptions.NewConnectionError: <urllib3.connection.VerifiedHTTPSConnection object at 0x7f8508c2a9d0>: Failed to establish a new connection: [Errno -3] Temporary failure in name resolution

During handling of the above exception, another exception occurred:

Traceback (most recent call last):
  File "/home/sergio/github/algotrader/Datagraber.py", line 117, in <module>
    [x.update(ohlcurl+x.tick,macdurl+x.tick,'5min') for x in symbolsdata]
  File "/home/sergio/github/algotrader/Datagraber.py", line 117, in <listcomp>
    [x.update(ohlcurl+x.tick,macdurl+x.tick,'5min') for x in symbolsdata]
  File "/home/sergio/github/algotrader/Datagraber.py", line 74, in update
    ohlctmp=json.loads(http.request('GET', ohlcurl).data)
  File "/home/sergio/anaconda3/lib/python3.7/site-packages/urllib3/request.py", line 76, in request
    method, url, fields=fields, headers=headers, **urlopen_kw
  File "/home/sergio/anaconda3/lib/python3.7/site-packages/urllib3/request.py", line 97, in request_encode_url
    return self.urlopen(method, url, **extra_kw)
  File "/home/sergio/anaconda3/lib/python3.7/site-packages/urllib3/poolmanager.py", line 330, in urlopen
    response = conn.urlopen(method, u.request_uri, **kw)
  File "/home/sergio/anaconda3/lib/python3.7/site-packages/urllib3/connectionpool.py", line 760, in urlopen
    **response_kw
  File "/home/sergio/anaconda3/lib/python3.7/site-packages/urllib3/connectionpool.py", line 760, in urlopen
    **response_kw
  File "/home/sergio/anaconda3/lib/python3.7/site-packages/urllib3/connectionpool.py", line 760, in urlopen
    **response_kw
  File "/home/sergio/anaconda3/lib/python3.7/site-packages/urllib3/connectionpool.py", line 720, in urlopen
    method, url, error=e, _pool=self, _stacktrace=sys.exc_info()[2]
  File "/home/sergio/anaconda3/lib/python3.7/site-packages/urllib3/util/retry.py", line 436, in increment
    raise MaxRetryError(_pool, url, error or ResponseError(cause))
urllib3.exceptions.MaxRetryError: HTTPSConnectionPool(host='www.alphavantage.co', port=443): Max retries exceeded with url: /query?function=TIME_SERIES_INTRADAY&interval=5min&apikey=46O5MSJ0J745T9J8&outputsize=full&symbol=TSLA (Caused by NewConnectionError('<urllib3.connection.VerifiedHTTPSConnection object at 0x7f8508c2a9d0>: Failed to establish a new connection: [Errno -3] Temporary failure in name resolution'))
Traceback (most recent call last):
  File "/home/sergio/anaconda3/lib/python3.7/site-packages/urllib3/connection.py", line 157, in _new_conn
    (self._dns_host, self.port), self.timeout, **extra_kw
  File "/home/sergio/anaconda3/lib/python3.7/site-packages/urllib3/util/connection.py", line 61, in create_connection
    for res in socket.getaddrinfo(host, port, family, socket.SOCK_STREAM):
  File "/home/sergio/anaconda3/lib/python3.7/socket.py", line 748, in getaddrinfo
    for res in _socket.getaddrinfo(host, port, family, type, proto, flags):
socket.gaierror: [Errno -3] Temporary failure in name resolution

During handling of the above exception, another exception occurred:

Traceback (most recent call last):
  File "/home/sergio/anaconda3/lib/python3.7/site-packages/urllib3/connectionpool.py", line 672, in urlopen
    chunked=chunked,
  File "/home/sergio/anaconda3/lib/python3.7/site-packages/urllib3/connectionpool.py", line 376, in _make_request
    self._validate_conn(conn)
  File "/home/sergio/anaconda3/lib/python3.7/site-packages/urllib3/connectionpool.py", line 994, in _validate_conn
    conn.connect()
  File "/home/sergio/anaconda3/lib/python3.7/site-packages/urllib3/connection.py", line 300, in connect
    conn = self._new_conn()
  File "/home/sergio/anaconda3/lib/python3.7/site-packages/urllib3/connection.py", line 169, in _new_conn
    self, "Failed to establish a new connection: %s" % e
urllib3.exceptions.NewConnectionError: <urllib3.connection.VerifiedHTTPSConnection object at 0x7f78b5432910>: Failed to establish a new connection: [Errno -3] Temporary failure in name resolution

During handling of the above exception, another exception occurred:

Traceback (most recent call last):
  File "/home/sergio/github/algotrader/Datagraber.py", line 117, in <module>
    [x.update(ohlcurl+x.tick,macdurl+x.tick,'5min') for x in symbolsdata]
  File "/home/sergio/github/algotrader/Datagraber.py", line 117, in <listcomp>
    [x.update(ohlcurl+x.tick,macdurl+x.tick,'5min') for x in symbolsdata]
  File "/home/sergio/github/algotrader/Datagraber.py", line 74, in update
    ohlctmp=json.loads(http.request('GET', ohlcurl).data)
  File "/home/sergio/anaconda3/lib/python3.7/site-packages/urllib3/request.py", line 76, in request
    method, url, fields=fields, headers=headers, **urlopen_kw
  File "/home/sergio/anaconda3/lib/python3.7/site-packages/urllib3/request.py", line 97, in request_encode_url
    return self.urlopen(method, url, **extra_kw)
  File "/home/sergio/anaconda3/lib/python3.7/site-packages/urllib3/poolmanager.py", line 330, in urlopen
    response = conn.urlopen(method, u.request_uri, **kw)
  File "/home/sergio/anaconda3/lib/python3.7/site-packages/urllib3/connectionpool.py", line 760, in urlopen
    **response_kw
  File "/home/sergio/anaconda3/lib/python3.7/site-packages/urllib3/connectionpool.py", line 760, in urlopen
    **response_kw
  File "/home/sergio/anaconda3/lib/python3.7/site-packages/urllib3/connectionpool.py", line 760, in urlopen
    **response_kw
  File "/home/sergio/anaconda3/lib/python3.7/site-packages/urllib3/connectionpool.py", line 720, in urlopen
    method, url, error=e, _pool=self, _stacktrace=sys.exc_info()[2]
  File "/home/sergio/anaconda3/lib/python3.7/site-packages/urllib3/util/retry.py", line 436, in increment
    raise MaxRetryError(_pool, url, error or ResponseError(cause))
urllib3.exceptions.MaxRetryError: HTTPSConnectionPool(host='www.alphavantage.co', port=443): Max retries exceeded with url: /query?function=TIME_SERIES_INTRADAY&interval=5min&apikey=46O5MSJ0J745T9J8&outputsize=full&symbol=TSLA (Caused by NewConnectionError('<urllib3.connection.VerifiedHTTPSConnection object at 0x7f78b5432910>: Failed to establish a new connection: [Errno -3] Temporary failure in name resolution'))
dict_keys(['Meta Data', 'Time Series (5min)'])
1143
dict_keys(['Meta Data', 'Time Series (5min)'])
1143
dict_keys(['Meta Data', 'Time Series (5min)'])
1139
dict_keys(['Meta Data', 'Time Series (5min)'])
1136
dict_keys(['Meta Data', 'Time Series (5min)'])
1140
dict_keys(['Meta Data', 'Time Series (5min)'])
1144
dict_keys(['Meta Data', 'Time Series (5min)'])
1144
dict_keys(['Meta Data', 'Time Series (5min)'])
14
Traceback (most recent call last):
  File "/home/sergio/anaconda3/lib/python3.7/site-packages/urllib3/connection.py", line 157, in _new_conn
    (self._dns_host, self.port), self.timeout, **extra_kw
  File "/home/sergio/anaconda3/lib/python3.7/site-packages/urllib3/util/connection.py", line 61, in create_connection
    for res in socket.getaddrinfo(host, port, family, socket.SOCK_STREAM):
  File "/home/sergio/anaconda3/lib/python3.7/socket.py", line 748, in getaddrinfo
    for res in _socket.getaddrinfo(host, port, family, type, proto, flags):
socket.gaierror: [Errno -3] Temporary failure in name resolution

During handling of the above exception, another exception occurred:

Traceback (most recent call last):
  File "/home/sergio/anaconda3/lib/python3.7/site-packages/urllib3/connectionpool.py", line 672, in urlopen
    chunked=chunked,
  File "/home/sergio/anaconda3/lib/python3.7/site-packages/urllib3/connectionpool.py", line 376, in _make_request
    self._validate_conn(conn)
  File "/home/sergio/anaconda3/lib/python3.7/site-packages/urllib3/connectionpool.py", line 994, in _validate_conn
    conn.connect()
  File "/home/sergio/anaconda3/lib/python3.7/site-packages/urllib3/connection.py", line 300, in connect
    conn = self._new_conn()
  File "/home/sergio/anaconda3/lib/python3.7/site-packages/urllib3/connection.py", line 169, in _new_conn
    self, "Failed to establish a new connection: %s" % e
urllib3.exceptions.NewConnectionError: <urllib3.connection.VerifiedHTTPSConnection object at 0x7fbd25927090>: Failed to establish a new connection: [Errno -3] Temporary failure in name resolution

During handling of the above exception, another exception occurred:

Traceback (most recent call last):
  File "/home/sergio/github/algotrader/Datagraber.py", line 117, in <module>
    [x.update(ohlcurl+x.tick,macdurl+x.tick,'5min') for x in symbolsdata]
  File "/home/sergio/github/algotrader/Datagraber.py", line 117, in <listcomp>
    [x.update(ohlcurl+x.tick,macdurl+x.tick,'5min') for x in symbolsdata]
  File "/home/sergio/github/algotrader/Datagraber.py", line 74, in update
    ohlctmp=json.loads(http.request('GET', ohlcurl).data)
  File "/home/sergio/anaconda3/lib/python3.7/site-packages/urllib3/request.py", line 76, in request
    method, url, fields=fields, headers=headers, **urlopen_kw
  File "/home/sergio/anaconda3/lib/python3.7/site-packages/urllib3/request.py", line 97, in request_encode_url
    return self.urlopen(method, url, **extra_kw)
  File "/home/sergio/anaconda3/lib/python3.7/site-packages/urllib3/poolmanager.py", line 330, in urlopen
    response = conn.urlopen(method, u.request_uri, **kw)
  File "/home/sergio/anaconda3/lib/python3.7/site-packages/urllib3/connectionpool.py", line 760, in urlopen
    **response_kw
  File "/home/sergio/anaconda3/lib/python3.7/site-packages/urllib3/connectionpool.py", line 760, in urlopen
    **response_kw
  File "/home/sergio/anaconda3/lib/python3.7/site-packages/urllib3/connectionpool.py", line 760, in urlopen
    **response_kw
  File "/home/sergio/anaconda3/lib/python3.7/site-packages/urllib3/connectionpool.py", line 720, in urlopen
    method, url, error=e, _pool=self, _stacktrace=sys.exc_info()[2]
  File "/home/sergio/anaconda3/lib/python3.7/site-packages/urllib3/util/retry.py", line 436, in increment
    raise MaxRetryError(_pool, url, error or ResponseError(cause))
urllib3.exceptions.MaxRetryError: HTTPSConnectionPool(host='www.alphavantage.co', port=443): Max retries exceeded with url: /query?function=TIME_SERIES_INTRADAY&interval=5min&apikey=46O5MSJ0J745T9J8&outputsize=full&symbol=TSLA (Caused by NewConnectionError('<urllib3.connection.VerifiedHTTPSConnection object at 0x7fbd25927090>: Failed to establish a new connection: [Errno -3] Temporary failure in name resolution'))
Traceback (most recent call last):
  File "/home/sergio/anaconda3/lib/python3.7/site-packages/urllib3/connection.py", line 157, in _new_conn
    (self._dns_host, self.port), self.timeout, **extra_kw
  File "/home/sergio/anaconda3/lib/python3.7/site-packages/urllib3/util/connection.py", line 61, in create_connection
    for res in socket.getaddrinfo(host, port, family, socket.SOCK_STREAM):
  File "/home/sergio/anaconda3/lib/python3.7/socket.py", line 748, in getaddrinfo
    for res in _socket.getaddrinfo(host, port, family, type, proto, flags):
socket.gaierror: [Errno -3] Temporary failure in name resolution

During handling of the above exception, another exception occurred:

Traceback (most recent call last):
  File "/home/sergio/anaconda3/lib/python3.7/site-packages/urllib3/connectionpool.py", line 672, in urlopen
    chunked=chunked,
  File "/home/sergio/anaconda3/lib/python3.7/site-packages/urllib3/connectionpool.py", line 376, in _make_request
    self._validate_conn(conn)
  File "/home/sergio/anaconda3/lib/python3.7/site-packages/urllib3/connectionpool.py", line 994, in _validate_conn
    conn.connect()
  File "/home/sergio/anaconda3/lib/python3.7/site-packages/urllib3/connection.py", line 300, in connect
    conn = self._new_conn()
  File "/home/sergio/anaconda3/lib/python3.7/site-packages/urllib3/connection.py", line 169, in _new_conn
    self, "Failed to establish a new connection: %s" % e
urllib3.exceptions.NewConnectionError: <urllib3.connection.VerifiedHTTPSConnection object at 0x7f7df7dc2610>: Failed to establish a new connection: [Errno -3] Temporary failure in name resolution

During handling of the above exception, another exception occurred:

Traceback (most recent call last):
  File "/home/sergio/github/algotrader/Datagraber.py", line 117, in <module>
    [x.update(ohlcurl+x.tick,macdurl+x.tick,'5min') for x in symbolsdata]
  File "/home/sergio/github/algotrader/Datagraber.py", line 117, in <listcomp>
    [x.update(ohlcurl+x.tick,macdurl+x.tick,'5min') for x in symbolsdata]
  File "/home/sergio/github/algotrader/Datagraber.py", line 74, in update
    ohlctmp=json.loads(http.request('GET', ohlcurl).data)
  File "/home/sergio/anaconda3/lib/python3.7/site-packages/urllib3/request.py", line 76, in request
    method, url, fields=fields, headers=headers, **urlopen_kw
  File "/home/sergio/anaconda3/lib/python3.7/site-packages/urllib3/request.py", line 97, in request_encode_url
    return self.urlopen(method, url, **extra_kw)
  File "/home/sergio/anaconda3/lib/python3.7/site-packages/urllib3/poolmanager.py", line 330, in urlopen
    response = conn.urlopen(method, u.request_uri, **kw)
  File "/home/sergio/anaconda3/lib/python3.7/site-packages/urllib3/connectionpool.py", line 760, in urlopen
    **response_kw
  File "/home/sergio/anaconda3/lib/python3.7/site-packages/urllib3/connectionpool.py", line 760, in urlopen
    **response_kw
  File "/home/sergio/anaconda3/lib/python3.7/site-packages/urllib3/connectionpool.py", line 760, in urlopen
    **response_kw
  File "/home/sergio/anaconda3/lib/python3.7/site-packages/urllib3/connectionpool.py", line 720, in urlopen
    method, url, error=e, _pool=self, _stacktrace=sys.exc_info()[2]
  File "/home/sergio/anaconda3/lib/python3.7/site-packages/urllib3/util/retry.py", line 436, in increment
    raise MaxRetryError(_pool, url, error or ResponseError(cause))
urllib3.exceptions.MaxRetryError: HTTPSConnectionPool(host='www.alphavantage.co', port=443): Max retries exceeded with url: /query?function=TIME_SERIES_INTRADAY&interval=5min&apikey=46O5MSJ0J745T9J8&outputsize=full&symbol=TSLA (Caused by NewConnectionError('<urllib3.connection.VerifiedHTTPSConnection object at 0x7f7df7dc2610>: Failed to establish a new connection: [Errno -3] Temporary failure in name resolution'))
Traceback (most recent call last):
  File "/home/sergio/anaconda3/lib/python3.7/site-packages/urllib3/connection.py", line 157, in _new_conn
    (self._dns_host, self.port), self.timeout, **extra_kw
  File "/home/sergio/anaconda3/lib/python3.7/site-packages/urllib3/util/connection.py", line 61, in create_connection
    for res in socket.getaddrinfo(host, port, family, socket.SOCK_STREAM):
  File "/home/sergio/anaconda3/lib/python3.7/socket.py", line 748, in getaddrinfo
    for res in _socket.getaddrinfo(host, port, family, type, proto, flags):
socket.gaierror: [Errno -3] Temporary failure in name resolution

During handling of the above exception, another exception occurred:

Traceback (most recent call last):
  File "/home/sergio/anaconda3/lib/python3.7/site-packages/urllib3/connectionpool.py", line 672, in urlopen
    chunked=chunked,
  File "/home/sergio/anaconda3/lib/python3.7/site-packages/urllib3/connectionpool.py", line 376, in _make_request
    self._validate_conn(conn)
  File "/home/sergio/anaconda3/lib/python3.7/site-packages/urllib3/connectionpool.py", line 994, in _validate_conn
    conn.connect()
  File "/home/sergio/anaconda3/lib/python3.7/site-packages/urllib3/connection.py", line 300, in connect
    conn = self._new_conn()
  File "/home/sergio/anaconda3/lib/python3.7/site-packages/urllib3/connection.py", line 169, in _new_conn
    self, "Failed to establish a new connection: %s" % e
urllib3.exceptions.NewConnectionError: <urllib3.connection.VerifiedHTTPSConnection object at 0x7f947de5e710>: Failed to establish a new connection: [Errno -3] Temporary failure in name resolution

During handling of the above exception, another exception occurred:

Traceback (most recent call last):
  File "/home/sergio/github/algotrader/Datagraber.py", line 117, in <module>
    [x.update(ohlcurl+x.tick,macdurl+x.tick,'5min') for x in symbolsdata]
  File "/home/sergio/github/algotrader/Datagraber.py", line 117, in <listcomp>
    [x.update(ohlcurl+x.tick,macdurl+x.tick,'5min') for x in symbolsdata]
  File "/home/sergio/github/algotrader/Datagraber.py", line 74, in update
    ohlctmp=json.loads(http.request('GET', ohlcurl).data)
  File "/home/sergio/anaconda3/lib/python3.7/site-packages/urllib3/request.py", line 76, in request
    method, url, fields=fields, headers=headers, **urlopen_kw
  File "/home/sergio/anaconda3/lib/python3.7/site-packages/urllib3/request.py", line 97, in request_encode_url
    return self.urlopen(method, url, **extra_kw)
  File "/home/sergio/anaconda3/lib/python3.7/site-packages/urllib3/poolmanager.py", line 330, in urlopen
    response = conn.urlopen(method, u.request_uri, **kw)
  File "/home/sergio/anaconda3/lib/python3.7/site-packages/urllib3/connectionpool.py", line 760, in urlopen
    **response_kw
  File "/home/sergio/anaconda3/lib/python3.7/site-packages/urllib3/connectionpool.py", line 760, in urlopen
    **response_kw
  File "/home/sergio/anaconda3/lib/python3.7/site-packages/urllib3/connectionpool.py", line 760, in urlopen
    **response_kw
  File "/home/sergio/anaconda3/lib/python3.7/site-packages/urllib3/connectionpool.py", line 720, in urlopen
    method, url, error=e, _pool=self, _stacktrace=sys.exc_info()[2]
  File "/home/sergio/anaconda3/lib/python3.7/site-packages/urllib3/util/retry.py", line 436, in increment
    raise MaxRetryError(_pool, url, error or ResponseError(cause))
urllib3.exceptions.MaxRetryError: HTTPSConnectionPool(host='www.alphavantage.co', port=443): Max retries exceeded with url: /query?function=TIME_SERIES_INTRADAY&interval=5min&apikey=46O5MSJ0J745T9J8&outputsize=full&symbol=TSLA (Caused by NewConnectionError('<urllib3.connection.VerifiedHTTPSConnection object at 0x7f947de5e710>: Failed to establish a new connection: [Errno -3] Temporary failure in name resolution'))
dict_keys(['Meta Data', 'Time Series (5min)'])
1101
dict_keys(['Meta Data', 'Time Series (5min)'])
1101
dict_keys(['Meta Data', 'Time Series (5min)'])
1097
dict_keys(['Meta Data', 'Time Series (5min)'])
1094
dict_keys(['Meta Data', 'Time Series (5min)'])
1094
dict_keys(['Meta Data', 'Time Series (5min)'])
1099
dict_keys(['Meta Data', 'Time Series (5min)'])
1102
dict_keys(['Meta Data', 'Time Series (5min)'])
14
dict_keys(['Meta Data', 'Time Series (5min)'])
1104
dict_keys(['Meta Data', 'Time Series (5min)'])
1104
dict_keys(['Meta Data', 'Time Series (5min)'])
1096
dict_keys(['Meta Data', 'Time Series (5min)'])
1100
dict_keys(['Meta Data', 'Time Series (5min)'])
1096
dict_keys(['Meta Data', 'Time Series (5min)'])
1102
dict_keys(['Meta Data', 'Time Series (5min)'])
1105
dict_keys(['Meta Data', 'Time Series (5min)'])
14
dict_keys(['Meta Data', 'Time Series (5min)'])
1106
dict_keys(['Note'])
Traceback (most recent call last):
  File "/home/sergio/github/algotrader/Datagraber.py", line 117, in <module>
    [x.update(ohlcurl+x.tick,macdurl+x.tick,'5min') for x in symbolsdata]
  File "/home/sergio/github/algotrader/Datagraber.py", line 117, in <listcomp>
    [x.update(ohlcurl+x.tick,macdurl+x.tick,'5min') for x in symbolsdata]
  File "/home/sergio/github/algotrader/Datagraber.py", line 76, in update
    ohlcdata=ohlctmp['Time Series ('+interval+')']
KeyError: 'Time Series (5min)'
dict_keys(['Meta Data', 'Time Series (5min)'])
{'Note': 'Thank you for using Alpha Vantage! Our standard API call frequency is 5 calls per minute and 500 calls per day. Please visit https://www.alphavantage.co/premium/ if you would like to target a higher API call frequency.'}
1106
Traceback (most recent call last):
  File "/home/sergio/github/algotrader/Datagraber.py", line 117, in <module>
    [x.update(ohlcurl+x.tick,macdurl+x.tick,'5min') for x in symbolsdata]
  File "/home/sergio/github/algotrader/Datagraber.py", line 117, in <listcomp>
    [x.update(ohlcurl+x.tick,macdurl+x.tick,'5min') for x in symbolsdata]
  File "/home/sergio/github/algotrader/Datagraber.py", line 85, in update
    for keyo,keym in zip(list(ohlcdata.keys()),list(macddata.keys())):
UnboundLocalError: local variable 'macddata' referenced before assignment
dict_keys(['Meta Data', 'Time Series (5min)'])
1106
dict_keys(['Note'])
Traceback (most recent call last):
  File "/home/sergio/github/algotrader/Datagraber.py", line 117, in <module>
    [x.update(ohlcurl+x.tick,macdurl+x.tick,'5min') for x in symbolsdata]
  File "/home/sergio/github/algotrader/Datagraber.py", line 117, in <listcomp>
    [x.update(ohlcurl+x.tick,macdurl+x.tick,'5min') for x in symbolsdata]
  File "/home/sergio/github/algotrader/Datagraber.py", line 76, in update
    ohlcdata=ohlctmp['Time Series ('+interval+')']
KeyError: 'Time Series (5min)'
dict_keys(['Meta Data', 'Time Series (5min)'])
1110
dict_keys(['Meta Data', 'Time Series (5min)'])
1110
dict_keys(['Meta Data', 'Time Series (5min)'])
1106
dict_keys(['Meta Data', 'Time Series (5min)'])
1107
dict_keys(['Meta Data', 'Time Series (5min)'])
1107
dict_keys(['Meta Data', 'Time Series (5min)'])
1108
dict_keys(['Meta Data', 'Time Series (5min)'])
1111
dict_keys(['Meta Data', 'Time Series (5min)'])
14
Traceback (most recent call last):
  File "/home/sergio/anaconda3/lib/python3.7/site-packages/urllib3/connection.py", line 157, in _new_conn
    (self._dns_host, self.port), self.timeout, **extra_kw
  File "/home/sergio/anaconda3/lib/python3.7/site-packages/urllib3/util/connection.py", line 61, in create_connection
    for res in socket.getaddrinfo(host, port, family, socket.SOCK_STREAM):
  File "/home/sergio/anaconda3/lib/python3.7/socket.py", line 748, in getaddrinfo
    for res in _socket.getaddrinfo(host, port, family, type, proto, flags):
socket.gaierror: [Errno -3] Temporary failure in name resolution

During handling of the above exception, another exception occurred:

Traceback (most recent call last):
  File "/home/sergio/anaconda3/lib/python3.7/site-packages/urllib3/connectionpool.py", line 672, in urlopen
    chunked=chunked,
  File "/home/sergio/anaconda3/lib/python3.7/site-packages/urllib3/connectionpool.py", line 376, in _make_request
    self._validate_conn(conn)
  File "/home/sergio/anaconda3/lib/python3.7/site-packages/urllib3/connectionpool.py", line 994, in _validate_conn
    conn.connect()
  File "/home/sergio/anaconda3/lib/python3.7/site-packages/urllib3/connection.py", line 300, in connect
    conn = self._new_conn()
  File "/home/sergio/anaconda3/lib/python3.7/site-packages/urllib3/connection.py", line 169, in _new_conn
    self, "Failed to establish a new connection: %s" % e
urllib3.exceptions.NewConnectionError: <urllib3.connection.VerifiedHTTPSConnection object at 0x7fcb3c64bc50>: Failed to establish a new connection: [Errno -3] Temporary failure in name resolution

During handling of the above exception, another exception occurred:

Traceback (most recent call last):
  File "/home/sergio/github/algotrader/Datagraber.py", line 117, in <module>
    [x.update(ohlcurl+x.tick,macdurl+x.tick,'5min') for x in symbolsdata]
  File "/home/sergio/github/algotrader/Datagraber.py", line 117, in <listcomp>
    [x.update(ohlcurl+x.tick,macdurl+x.tick,'5min') for x in symbolsdata]
  File "/home/sergio/github/algotrader/Datagraber.py", line 74, in update
    ohlctmp=json.loads(http.request('GET', ohlcurl).data)
  File "/home/sergio/anaconda3/lib/python3.7/site-packages/urllib3/request.py", line 76, in request
    method, url, fields=fields, headers=headers, **urlopen_kw
  File "/home/sergio/anaconda3/lib/python3.7/site-packages/urllib3/request.py", line 97, in request_encode_url
    return self.urlopen(method, url, **extra_kw)
  File "/home/sergio/anaconda3/lib/python3.7/site-packages/urllib3/poolmanager.py", line 330, in urlopen
    response = conn.urlopen(method, u.request_uri, **kw)
  File "/home/sergio/anaconda3/lib/python3.7/site-packages/urllib3/connectionpool.py", line 760, in urlopen
    **response_kw
  File "/home/sergio/anaconda3/lib/python3.7/site-packages/urllib3/connectionpool.py", line 760, in urlopen
    **response_kw
  File "/home/sergio/anaconda3/lib/python3.7/site-packages/urllib3/connectionpool.py", line 760, in urlopen
    **response_kw
  File "/home/sergio/anaconda3/lib/python3.7/site-packages/urllib3/connectionpool.py", line 720, in urlopen
    method, url, error=e, _pool=self, _stacktrace=sys.exc_info()[2]
  File "/home/sergio/anaconda3/lib/python3.7/site-packages/urllib3/util/retry.py", line 436, in increment
    raise MaxRetryError(_pool, url, error or ResponseError(cause))
urllib3.exceptions.MaxRetryError: HTTPSConnectionPool(host='www.alphavantage.co', port=443): Max retries exceeded with url: /query?function=TIME_SERIES_INTRADAY&interval=5min&apikey=46O5MSJ0J745T9J8&outputsize=full&symbol=TSLA (Caused by NewConnectionError('<urllib3.connection.VerifiedHTTPSConnection object at 0x7fcb3c64bc50>: Failed to establish a new connection: [Errno -3] Temporary failure in name resolution'))
dict_keys(['Meta Data', 'Time Series (5min)'])
1166
dict_keys(['Meta Data', 'Time Series (5min)'])
1166
dict_keys(['Meta Data', 'Time Series (5min)'])
1162
dict_keys(['Meta Data', 'Time Series (5min)'])
1162
dict_keys(['Meta Data', 'Time Series (5min)'])
1158
dict_keys(['Meta Data', 'Time Series (5min)'])
1163
dict_keys(['Meta Data', 'Time Series (5min)'])
1166
dict_keys(['Meta Data', 'Time Series (5min)'])
15
dict_keys(['Meta Data', 'Time Series (5min)'])
1166
dict_keys(['Meta Data', 'Time Series (5min)'])
1166
dict_keys(['Meta Data', 'Time Series (5min)'])
1162
dict_keys(['Meta Data', 'Time Series (5min)'])
1162
dict_keys(['Meta Data', 'Time Series (5min)'])
1158
dict_keys(['Meta Data', 'Time Series (5min)'])
1163
dict_keys(['Meta Data', 'Time Series (5min)'])
1166
dict_keys(['Meta Data', 'Time Series (5min)'])
15
dict_keys(['Meta Data', 'Time Series (5min)'])
1166
dict_keys(['Note'])
Traceback (most recent call last):
  File "/home/sergio/github/algotrader/Datagraber.py", line 117, in <module>
    [x.update(ohlcurl+x.tick,macdurl+x.tick,'5min') for x in symbolsdata]
  File "/home/sergio/github/algotrader/Datagraber.py", line 117, in <listcomp>
    [x.update(ohlcurl+x.tick,macdurl+x.tick,'5min') for x in symbolsdata]
  File "/home/sergio/github/algotrader/Datagraber.py", line 76, in update
    ohlcdata=ohlctmp['Time Series ('+interval+')']
KeyError: 'Time Series (5min)'
dict_keys(['Meta Data', 'Time Series (5min)'])
1166
dict_keys(['Meta Data', 'Time Series (5min)'])
1166
dict_keys(['Meta Data', 'Time Series (5min)'])
1162
dict_keys(['Meta Data', 'Time Series (5min)'])
1162
dict_keys(['Meta Data', 'Time Series (5min)'])
1158
dict_keys(['Note'])
Traceback (most recent call last):
  File "/home/sergio/github/algotrader/Datagraber.py", line 117, in <module>
    [x.update(ohlcurl+x.tick,macdurl+x.tick,'5min') for x in symbolsdata]
  File "/home/sergio/github/algotrader/Datagraber.py", line 117, in <listcomp>
    [x.update(ohlcurl+x.tick,macdurl+x.tick,'5min') for x in symbolsdata]
  File "/home/sergio/github/algotrader/Datagraber.py", line 76, in update
    ohlcdata=ohlctmp['Time Series ('+interval+')']
KeyError: 'Time Series (5min)'
dict_keys(['Meta Data', 'Time Series (5min)'])
1166
dict_keys(['Meta Data', 'Time Series (5min)'])
1166
dict_keys(['Meta Data', 'Time Series (5min)'])
1162
dict_keys(['Meta Data', 'Time Series (5min)'])
1162
dict_keys(['Meta Data', 'Time Series (5min)'])
1162
dict_keys(['Meta Data', 'Time Series (5min)'])
1163
dict_keys(['Meta Data', 'Time Series (5min)'])
1166
dict_keys(['Meta Data', 'Time Series (5min)'])
15
dict_keys(['Note'])
Traceback (most recent call last):
  File "/home/sergio/github/algotrader/Datagraber.py", line 117, in <module>
    [x.update(ohlcurl+x.tick,macdurl+x.tick,'5min') for x in symbolsdata]
  File "/home/sergio/github/algotrader/Datagraber.py", line 117, in <listcomp>
    [x.update(ohlcurl+x.tick,macdurl+x.tick,'5min') for x in symbolsdata]
  File "/home/sergio/github/algotrader/Datagraber.py", line 76, in update
    ohlcdata=ohlctmp['Time Series ('+interval+')']
KeyError: 'Time Series (5min)'
dict_keys(['Meta Data', 'Time Series (5min)'])
1166
dict_keys(['Meta Data', 'Time Series (5min)'])
1166
dict_keys(['Meta Data', 'Time Series (5min)'])
1162
dict_keys(['Meta Data', 'Time Series (5min)'])
1158
dict_keys(['Meta Data', 'Time Series (5min)'])
1158
dict_keys(['Note'])
Traceback (most recent call last):
  File "/home/sergio/github/algotrader/Datagraber.py", line 117, in <module>
    [x.update(ohlcurl+x.tick,macdurl+x.tick,'5min') for x in symbolsdata]
  File "/home/sergio/github/algotrader/Datagraber.py", line 117, in <listcomp>
    [x.update(ohlcurl+x.tick,macdurl+x.tick,'5min') for x in symbolsdata]
  File "/home/sergio/github/algotrader/Datagraber.py", line 76, in update
    ohlcdata=ohlctmp['Time Series ('+interval+')']
KeyError: 'Time Series (5min)'
dict_keys(['Meta Data', 'Time Series (5min)'])
1166
dict_keys(['Meta Data', 'Time Series (5min)'])
{'Note': 'Thank you for using Alpha Vantage! Our standard API call frequency is 5 calls per minute and 500 calls per day. Please visit https://www.alphavantage.co/premium/ if you would like to target a higher API call frequency.'}
1166
Traceback (most recent call last):
  File "/home/sergio/github/algotrader/Datagraber.py", line 117, in <module>
    [x.update(ohlcurl+x.tick,macdurl+x.tick,'5min') for x in symbolsdata]
  File "/home/sergio/github/algotrader/Datagraber.py", line 117, in <listcomp>
    [x.update(ohlcurl+x.tick,macdurl+x.tick,'5min') for x in symbolsdata]
  File "/home/sergio/github/algotrader/Datagraber.py", line 85, in update
    for keyo,keym in zip(list(ohlcdata.keys()),list(macddata.keys())):
UnboundLocalError: local variable 'macddata' referenced before assignment
dict_keys(['Meta Data', 'Time Series (5min)'])
1166
dict_keys(['Meta Data', 'Time Series (5min)'])
1166
dict_keys(['Meta Data', 'Time Series (5min)'])
{'Note': 'Thank you for using Alpha Vantage! Our standard API call frequency is 5 calls per minute and 500 calls per day. Please visit https://www.alphavantage.co/premium/ if you would like to target a higher API call frequency.'}
1162
Traceback (most recent call last):
  File "/home/sergio/github/algotrader/Datagraber.py", line 117, in <module>
    [x.update(ohlcurl+x.tick,macdurl+x.tick,'5min') for x in symbolsdata]
  File "/home/sergio/github/algotrader/Datagraber.py", line 117, in <listcomp>
    [x.update(ohlcurl+x.tick,macdurl+x.tick,'5min') for x in symbolsdata]
  File "/home/sergio/github/algotrader/Datagraber.py", line 85, in update
    for keyo,keym in zip(list(ohlcdata.keys()),list(macddata.keys())):
UnboundLocalError: local variable 'macddata' referenced before assignment
dict_keys(['Meta Data', 'Time Series (5min)'])
1166
dict_keys(['Note'])
Traceback (most recent call last):
  File "/home/sergio/github/algotrader/Datagraber.py", line 117, in <module>
    [x.update(ohlcurl+x.tick,macdurl+x.tick,'5min') for x in symbolsdata]
  File "/home/sergio/github/algotrader/Datagraber.py", line 117, in <listcomp>
    [x.update(ohlcurl+x.tick,macdurl+x.tick,'5min') for x in symbolsdata]
  File "/home/sergio/github/algotrader/Datagraber.py", line 76, in update
    ohlcdata=ohlctmp['Time Series ('+interval+')']
KeyError: 'Time Series (5min)'
dict_keys(['Meta Data', 'Time Series (5min)'])
1166
dict_keys(['Meta Data', 'Time Series (5min)'])
1166
dict_keys(['Meta Data', 'Time Series (5min)'])
1158
dict_keys(['Meta Data', 'Time Series (5min)'])
1162
dict_keys(['Meta Data', 'Time Series (5min)'])
1158
dict_keys(['Meta Data', 'Time Series (5min)'])
1163
dict_keys(['Meta Data', 'Time Series (5min)'])
1166
dict_keys(['Meta Data', 'Time Series (5min)'])
15
dict_keys(['Meta Data', 'Time Series (5min)'])
1166
dict_keys(['Meta Data', 'Time Series (5min)'])
1166
dict_keys(['Meta Data', 'Time Series (5min)'])
1162
dict_keys(['Meta Data', 'Time Series (5min)'])
1158
dict_keys(['Meta Data', 'Time Series (5min)'])
1158
dict_keys(['Meta Data', 'Time Series (5min)'])
1163
dict_keys(['Meta Data', 'Time Series (5min)'])
1166
dict_keys(['Meta Data', 'Time Series (5min)'])
15
dict_keys(['Meta Data', 'Time Series (5min)'])
1166
dict_keys(['Meta Data', 'Time Series (5min)'])
1166
dict_keys(['Note'])
Traceback (most recent call last):
  File "/home/sergio/github/algotrader/Datagraber.py", line 117, in <module>
    [x.update(ohlcurl+x.tick,macdurl+x.tick,'5min') for x in symbolsdata]
  File "/home/sergio/github/algotrader/Datagraber.py", line 117, in <listcomp>
    [x.update(ohlcurl+x.tick,macdurl+x.tick,'5min') for x in symbolsdata]
  File "/home/sergio/github/algotrader/Datagraber.py", line 76, in update
    ohlcdata=ohlctmp['Time Series ('+interval+')']
KeyError: 'Time Series (5min)'
dict_keys(['Meta Data', 'Time Series (5min)'])
1166
dict_keys(['Meta Data', 'Time Series (5min)'])
1166
dict_keys(['Meta Data', 'Time Series (5min)'])
{'Note': 'Thank you for using Alpha Vantage! Our standard API call frequency is 5 calls per minute and 500 calls per day. Please visit https://www.alphavantage.co/premium/ if you would like to target a higher API call frequency.'}
1162
Traceback (most recent call last):
  File "/home/sergio/github/algotrader/Datagraber.py", line 117, in <module>
    [x.update(ohlcurl+x.tick,macdurl+x.tick,'5min') for x in symbolsdata]
  File "/home/sergio/github/algotrader/Datagraber.py", line 117, in <listcomp>
    [x.update(ohlcurl+x.tick,macdurl+x.tick,'5min') for x in symbolsdata]
  File "/home/sergio/github/algotrader/Datagraber.py", line 85, in update
    for keyo,keym in zip(list(ohlcdata.keys()),list(macddata.keys())):
UnboundLocalError: local variable 'macddata' referenced before assignment
dict_keys(['Meta Data', 'Time Series (5min)'])
1166
dict_keys(['Note'])
Traceback (most recent call last):
  File "/home/sergio/github/algotrader/Datagraber.py", line 117, in <module>
    [x.update(ohlcurl+x.tick,macdurl+x.tick,'5min') for x in symbolsdata]
  File "/home/sergio/github/algotrader/Datagraber.py", line 117, in <listcomp>
    [x.update(ohlcurl+x.tick,macdurl+x.tick,'5min') for x in symbolsdata]
  File "/home/sergio/github/algotrader/Datagraber.py", line 76, in update
    ohlcdata=ohlctmp['Time Series ('+interval+')']
KeyError: 'Time Series (5min)'
dict_keys(['Meta Data', 'Time Series (5min)'])
1166
dict_keys(['Meta Data', 'Time Series (5min)'])
1166
dict_keys(['Meta Data', 'Time Series (5min)'])
1162
dict_keys(['Meta Data', 'Time Series (5min)'])
1162
dict_keys(['Meta Data', 'Time Series (5min)'])
1158
dict_keys(['Meta Data', 'Time Series (5min)'])
1163
dict_keys(['Meta Data', 'Time Series (5min)'])
1166
dict_keys(['Meta Data', 'Time Series (5min)'])
{'Note': 'Thank you for using Alpha Vantage! Our standard API call frequency is 5 calls per minute and 500 calls per day. Please visit https://www.alphavantage.co/premium/ if you would like to target a higher API call frequency.'}
15
Traceback (most recent call last):
  File "/home/sergio/github/algotrader/Datagraber.py", line 117, in <module>
    [x.update(ohlcurl+x.tick,macdurl+x.tick,'5min') for x in symbolsdata]
  File "/home/sergio/github/algotrader/Datagraber.py", line 117, in <listcomp>
    [x.update(ohlcurl+x.tick,macdurl+x.tick,'5min') for x in symbolsdata]
  File "/home/sergio/github/algotrader/Datagraber.py", line 85, in update
    for keyo,keym in zip(list(ohlcdata.keys()),list(macddata.keys())):
UnboundLocalError: local variable 'macddata' referenced before assignment
dict_keys(['Meta Data', 'Time Series (5min)'])
1166
dict_keys(['Meta Data', 'Time Series (5min)'])
1166
dict_keys(['Note'])
Traceback (most recent call last):
  File "/home/sergio/github/algotrader/Datagraber.py", line 117, in <module>
    [x.update(ohlcurl+x.tick,macdurl+x.tick,'5min') for x in symbolsdata]
  File "/home/sergio/github/algotrader/Datagraber.py", line 117, in <listcomp>
    [x.update(ohlcurl+x.tick,macdurl+x.tick,'5min') for x in symbolsdata]
  File "/home/sergio/github/algotrader/Datagraber.py", line 76, in update
    ohlcdata=ohlctmp['Time Series ('+interval+')']
KeyError: 'Time Series (5min)'
dict_keys(['Meta Data', 'Time Series (5min)'])
1166
dict_keys(['Meta Data', 'Time Series (5min)'])
1166
dict_keys(['Meta Data', 'Time Series (5min)'])
1158
dict_keys(['Meta Data', 'Time Series (5min)'])
1162
dict_keys(['Meta Data', 'Time Series (5min)'])
1158
dict_keys(['Meta Data', 'Time Series (5min)'])
1163
dict_keys(['Meta Data', 'Time Series (5min)'])
1166
dict_keys(['Meta Data', 'Time Series (5min)'])
15
dict_keys(['Meta Data', 'Time Series (5min)'])
1166
dict_keys(['Meta Data', 'Time Series (5min)'])
1166
dict_keys(['Meta Data', 'Time Series (5min)'])
1158
dict_keys(['Meta Data', 'Time Series (5min)'])
1158
dict_keys(['Meta Data', 'Time Series (5min)'])
1158
dict_keys(['Meta Data', 'Time Series (5min)'])
1163
dict_keys(['Meta Data', 'Time Series (5min)'])
1166
dict_keys(['Meta Data', 'Time Series (5min)'])
15
dict_keys(['Meta Data', 'Time Series (5min)'])
1101
dict_keys(['Meta Data', 'Time Series (5min)'])
1101
dict_keys(['Meta Data', 'Time Series (5min)'])
1097
dict_keys(['Meta Data', 'Time Series (5min)'])
1093
dict_keys(['Meta Data', 'Time Series (5min)'])
1097
dict_keys(['Meta Data', 'Time Series (5min)'])
1098
dict_keys(['Meta Data', 'Time Series (5min)'])
1101
dict_keys(['Meta Data', 'Time Series (5min)'])
14
dict_keys(['Meta Data', 'Time Series (5min)'])
1166
dict_keys(['Meta Data', 'Time Series (5min)'])
1166
dict_keys(['Meta Data', 'Time Series (5min)'])
1162
dict_keys(['Meta Data', 'Time Series (5min)'])
1158
dict_keys(['Meta Data', 'Time Series (5min)'])
1158
dict_keys(['Meta Data', 'Time Series (5min)'])
1163
dict_keys(['Meta Data', 'Time Series (5min)'])
1166
dict_keys(['Meta Data', 'Time Series (5min)'])
14
dict_keys(['Meta Data', 'Time Series (5min)'])
1166
dict_keys(['Meta Data', 'Time Series (5min)'])
1166
dict_keys(['Meta Data', 'Time Series (5min)'])
1162
dict_keys(['Meta Data', 'Time Series (5min)'])
1162
dict_keys(['Meta Data', 'Time Series (5min)'])
1162
dict_keys(['Meta Data', 'Time Series (5min)'])
1163
dict_keys(['Meta Data', 'Time Series (5min)'])
1166
dict_keys(['Meta Data', 'Time Series (5min)'])
14
dict_keys(['Meta Data', 'Time Series (5min)'])
1166
dict_keys(['Meta Data', 'Time Series (5min)'])
1166
dict_keys(['Meta Data', 'Time Series (5min)'])
1162
dict_keys(['Meta Data', 'Time Series (5min)'])
1162
dict_keys(['Meta Data', 'Time Series (5min)'])
1162
dict_keys(['Meta Data', 'Time Series (5min)'])
1163
dict_keys(['Meta Data', 'Time Series (5min)'])
1166
dict_keys(['Meta Data', 'Time Series (5min)'])
14
dict_keys(['Meta Data', 'Time Series (5min)'])
{'Note': 'Thank you for using Alpha Vantage! Our standard API call frequency is 5 calls per minute and 500 calls per day. Please visit https://www.alphavantage.co/premium/ if you would like to target a higher API call frequency.'}
1166
Traceback (most recent call last):
  File "/home/sergio/github/algotrader/Datagraber.py", line 117, in <module>
    [x.update(ohlcurl+x.tick,macdurl+x.tick,'5min') for x in symbolsdata]
  File "/home/sergio/github/algotrader/Datagraber.py", line 117, in <listcomp>
    [x.update(ohlcurl+x.tick,macdurl+x.tick,'5min') for x in symbolsdata]
  File "/home/sergio/github/algotrader/Datagraber.py", line 85, in update
    for keyo,keym in zip(list(ohlcdata.keys()),list(macddata.keys())):
UnboundLocalError: local variable 'macddata' referenced before assignment
dict_keys(['Meta Data', 'Time Series (5min)'])
1166
dict_keys(['Note'])
Traceback (most recent call last):
  File "/home/sergio/github/algotrader/Datagraber.py", line 117, in <module>
    [x.update(ohlcurl+x.tick,macdurl+x.tick,'5min') for x in symbolsdata]
  File "/home/sergio/github/algotrader/Datagraber.py", line 117, in <listcomp>
    [x.update(ohlcurl+x.tick,macdurl+x.tick,'5min') for x in symbolsdata]
  File "/home/sergio/github/algotrader/Datagraber.py", line 76, in update
    ohlcdata=ohlctmp['Time Series ('+interval+')']
KeyError: 'Time Series (5min)'
dict_keys(['Meta Data', 'Time Series (5min)'])
1166
dict_keys(['Note'])
Traceback (most recent call last):
  File "/home/sergio/github/algotrader/Datagraber.py", line 117, in <module>
    [x.update(ohlcurl+x.tick,macdurl+x.tick,'5min') for x in symbolsdata]
  File "/home/sergio/github/algotrader/Datagraber.py", line 117, in <listcomp>
    [x.update(ohlcurl+x.tick,macdurl+x.tick,'5min') for x in symbolsdata]
  File "/home/sergio/github/algotrader/Datagraber.py", line 76, in update
    ohlcdata=ohlctmp['Time Series ('+interval+')']
KeyError: 'Time Series (5min)'
dict_keys(['Meta Data', 'Time Series (5min)'])
1166
dict_keys(['Meta Data', 'Time Series (5min)'])
1166
dict_keys(['Meta Data', 'Time Series (5min)'])
{'Note': 'Thank you for using Alpha Vantage! Our standard API call frequency is 5 calls per minute and 500 calls per day. Please visit https://www.alphavantage.co/premium/ if you would like to target a higher API call frequency.'}
1162
Traceback (most recent call last):
  File "/home/sergio/github/algotrader/Datagraber.py", line 117, in <module>
    [x.update(ohlcurl+x.tick,macdurl+x.tick,'5min') for x in symbolsdata]
  File "/home/sergio/github/algotrader/Datagraber.py", line 117, in <listcomp>
    [x.update(ohlcurl+x.tick,macdurl+x.tick,'5min') for x in symbolsdata]
  File "/home/sergio/github/algotrader/Datagraber.py", line 85, in update
    for keyo,keym in zip(list(ohlcdata.keys()),list(macddata.keys())):
UnboundLocalError: local variable 'macddata' referenced before assignment
dict_keys(['Meta Data', 'Time Series (5min)'])
1166
dict_keys(['Meta Data', 'Time Series (5min)'])
1166
dict_keys(['Note'])
Traceback (most recent call last):
  File "/home/sergio/github/algotrader/Datagraber.py", line 117, in <module>
    [x.update(ohlcurl+x.tick,macdurl+x.tick,'5min') for x in symbolsdata]
  File "/home/sergio/github/algotrader/Datagraber.py", line 117, in <listcomp>
    [x.update(ohlcurl+x.tick,macdurl+x.tick,'5min') for x in symbolsdata]
  File "/home/sergio/github/algotrader/Datagraber.py", line 76, in update
    ohlcdata=ohlctmp['Time Series ('+interval+')']
KeyError: 'Time Series (5min)'
dict_keys(['Meta Data', 'Time Series (5min)'])
1166
dict_keys(['Meta Data', 'Time Series (5min)'])
1166
dict_keys(['Meta Data', 'Time Series (5min)'])
1162
dict_keys(['Meta Data', 'Time Series (5min)'])
1158
dict_keys(['Meta Data', 'Time Series (5min)'])
1158
dict_keys(['Meta Data', 'Time Series (5min)'])
1163
dict_keys(['Meta Data', 'Time Series (5min)'])
1166
dict_keys(['Meta Data', 'Time Series (5min)'])
14
dict_keys(['Meta Data', 'Time Series (5min)'])
1166
dict_keys(['Meta Data', 'Time Series (5min)'])
1166
dict_keys(['Meta Data', 'Time Series (5min)'])
1162
dict_keys(['Meta Data', 'Time Series (5min)'])
1162
dict_keys(['Meta Data', 'Time Series (5min)'])
1158
dict_keys(['Meta Data', 'Time Series (5min)'])
1163
dict_keys(['Meta Data', 'Time Series (5min)'])
1166
dict_keys(['Meta Data', 'Time Series (5min)'])
14
dict_keys(['Meta Data', 'Time Series (5min)'])
1166
dict_keys(['Meta Data', 'Time Series (5min)'])
1166
dict_keys(['Meta Data', 'Time Series (5min)'])
1162
dict_keys(['Meta Data', 'Time Series (5min)'])
1162
dict_keys(['Meta Data', 'Time Series (5min)'])
1162
dict_keys(['Meta Data', 'Time Series (5min)'])
1163
dict_keys(['Meta Data', 'Time Series (5min)'])
1166
dict_keys(['Meta Data', 'Time Series (5min)'])
14
dict_keys(['Meta Data', 'Time Series (5min)'])
1166
dict_keys(['Meta Data', 'Time Series (5min)'])
1166
dict_keys(['Meta Data', 'Time Series (5min)'])
1162
dict_keys(['Meta Data', 'Time Series (5min)'])
1162
dict_keys(['Meta Data', 'Time Series (5min)'])
1158
dict_keys(['Meta Data', 'Time Series (5min)'])
1163
dict_keys(['Meta Data', 'Time Series (5min)'])
1166
dict_keys(['Meta Data', 'Time Series (5min)'])
14
dict_keys(['Meta Data', 'Time Series (5min)'])
1166
dict_keys(['Meta Data', 'Time Series (5min)'])
1166
dict_keys(['Meta Data', 'Time Series (5min)'])
{'Note': 'Thank you for using Alpha Vantage! Our standard API call frequency is 5 calls per minute and 500 calls per day. Please visit https://www.alphavantage.co/premium/ if you would like to target a higher API call frequency.'}
1158
Traceback (most recent call last):
  File "/home/sergio/github/algotrader/Datagraber.py", line 117, in <module>
    [x.update(ohlcurl+x.tick,macdurl+x.tick,'5min') for x in symbolsdata]
  File "/home/sergio/github/algotrader/Datagraber.py", line 117, in <listcomp>
    [x.update(ohlcurl+x.tick,macdurl+x.tick,'5min') for x in symbolsdata]
  File "/home/sergio/github/algotrader/Datagraber.py", line 85, in update
    for keyo,keym in zip(list(ohlcdata.keys()),list(macddata.keys())):
UnboundLocalError: local variable 'macddata' referenced before assignment
dict_keys(['Meta Data', 'Time Series (5min)'])
{'Note': 'Thank you for using Alpha Vantage! Our standard API call frequency is 5 calls per minute and 500 calls per day. Please visit https://www.alphavantage.co/premium/ if you would like to target a higher API call frequency.'}
1166
Traceback (most recent call last):
  File "/home/sergio/github/algotrader/Datagraber.py", line 117, in <module>
    [x.update(ohlcurl+x.tick,macdurl+x.tick,'5min') for x in symbolsdata]
  File "/home/sergio/github/algotrader/Datagraber.py", line 117, in <listcomp>
    [x.update(ohlcurl+x.tick,macdurl+x.tick,'5min') for x in symbolsdata]
  File "/home/sergio/github/algotrader/Datagraber.py", line 85, in update
    for keyo,keym in zip(list(ohlcdata.keys()),list(macddata.keys())):
UnboundLocalError: local variable 'macddata' referenced before assignment
dict_keys(['Meta Data', 'Time Series (5min)'])
1166
dict_keys(['Meta Data', 'Time Series (5min)'])
1166
dict_keys(['Meta Data', 'Time Series (5min)'])
1162
dict_keys(['Meta Data', 'Time Series (5min)'])
1158
dict_keys(['Note'])
Traceback (most recent call last):
  File "/home/sergio/github/algotrader/Datagraber.py", line 117, in <module>
    [x.update(ohlcurl+x.tick,macdurl+x.tick,'5min') for x in symbolsdata]
  File "/home/sergio/github/algotrader/Datagraber.py", line 117, in <listcomp>
    [x.update(ohlcurl+x.tick,macdurl+x.tick,'5min') for x in symbolsdata]
  File "/home/sergio/github/algotrader/Datagraber.py", line 76, in update
    ohlcdata=ohlctmp['Time Series ('+interval+')']
KeyError: 'Time Series (5min)'
dict_keys(['Meta Data', 'Time Series (5min)'])
1166
dict_keys(['Meta Data', 'Time Series (5min)'])
1166
dict_keys(['Note'])
Traceback (most recent call last):
  File "/home/sergio/github/algotrader/Datagraber.py", line 117, in <module>
    [x.update(ohlcurl+x.tick,macdurl+x.tick,'5min') for x in symbolsdata]
  File "/home/sergio/github/algotrader/Datagraber.py", line 117, in <listcomp>
    [x.update(ohlcurl+x.tick,macdurl+x.tick,'5min') for x in symbolsdata]
  File "/home/sergio/github/algotrader/Datagraber.py", line 76, in update
    ohlcdata=ohlctmp['Time Series ('+interval+')']
KeyError: 'Time Series (5min)'
dict_keys(['Note'])
Traceback (most recent call last):
  File "/home/sergio/github/algotrader/Datagraber.py", line 117, in <module>
    [x.update(ohlcurl+x.tick,macdurl+x.tick,'5min') for x in symbolsdata]
  File "/home/sergio/github/algotrader/Datagraber.py", line 117, in <listcomp>
    [x.update(ohlcurl+x.tick,macdurl+x.tick,'5min') for x in symbolsdata]
  File "/home/sergio/github/algotrader/Datagraber.py", line 76, in update
    ohlcdata=ohlctmp['Time Series ('+interval+')']
KeyError: 'Time Series (5min)'
dict_keys(['Meta Data', 'Time Series (5min)'])
1166
dict_keys(['Meta Data', 'Time Series (5min)'])
1166
dict_keys(['Note'])
Traceback (most recent call last):
  File "/home/sergio/github/algotrader/Datagraber.py", line 117, in <module>
    [x.update(ohlcurl+x.tick,macdurl+x.tick,'5min') for x in symbolsdata]
  File "/home/sergio/github/algotrader/Datagraber.py", line 117, in <listcomp>
    [x.update(ohlcurl+x.tick,macdurl+x.tick,'5min') for x in symbolsdata]
  File "/home/sergio/github/algotrader/Datagraber.py", line 76, in update
    ohlcdata=ohlctmp['Time Series ('+interval+')']
KeyError: 'Time Series (5min)'
dict_keys(['Meta Data', 'Time Series (5min)'])
1166
dict_keys(['Meta Data', 'Time Series (5min)'])
1166
dict_keys(['Note'])
Traceback (most recent call last):
  File "/home/sergio/github/algotrader/Datagraber.py", line 117, in <module>
    [x.update(ohlcurl+x.tick,macdurl+x.tick,'5min') for x in symbolsdata]
  File "/home/sergio/github/algotrader/Datagraber.py", line 117, in <listcomp>
    [x.update(ohlcurl+x.tick,macdurl+x.tick,'5min') for x in symbolsdata]
  File "/home/sergio/github/algotrader/Datagraber.py", line 76, in update
    ohlcdata=ohlctmp['Time Series ('+interval+')']
KeyError: 'Time Series (5min)'
dict_keys(['Meta Data', 'Time Series (5min)'])
1166
dict_keys(['Meta Data', 'Time Series (5min)'])
1166
dict_keys(['Meta Data', 'Time Series (5min)'])
1162
dict_keys(['Meta Data', 'Time Series (5min)'])
1162
dict_keys(['Meta Data', 'Time Series (5min)'])
1162
dict_keys(['Meta Data', 'Time Series (5min)'])
1163
dict_keys(['Meta Data', 'Time Series (5min)'])
1166
dict_keys(['Meta Data', 'Time Series (5min)'])
14
dict_keys(['Meta Data', 'Time Series (5min)'])
1166
dict_keys(['Meta Data', 'Time Series (5min)'])
{'Note': 'Thank you for using Alpha Vantage! Our standard API call frequency is 5 calls per minute and 500 calls per day. Please visit https://www.alphavantage.co/premium/ if you would like to target a higher API call frequency.'}
1166
Traceback (most recent call last):
  File "/home/sergio/github/algotrader/Datagraber.py", line 117, in <module>
    [x.update(ohlcurl+x.tick,macdurl+x.tick,'5min') for x in symbolsdata]
  File "/home/sergio/github/algotrader/Datagraber.py", line 117, in <listcomp>
    [x.update(ohlcurl+x.tick,macdurl+x.tick,'5min') for x in symbolsdata]
  File "/home/sergio/github/algotrader/Datagraber.py", line 85, in update
    for keyo,keym in zip(list(ohlcdata.keys()),list(macddata.keys())):
UnboundLocalError: local variable 'macddata' referenced before assignment
dict_keys(['Meta Data', 'Time Series (5min)'])
1166
dict_keys(['Meta Data', 'Time Series (5min)'])
1166
dict_keys(['Meta Data', 'Time Series (5min)'])
1162
dict_keys(['Meta Data', 'Time Series (5min)'])
1158
dict_keys(['Meta Data', 'Time Series (5min)'])
{'Note': 'Thank you for using Alpha Vantage! Our standard API call frequency is 5 calls per minute and 500 calls per day. Please visit https://www.alphavantage.co/premium/ if you would like to target a higher API call frequency.'}
1158
Traceback (most recent call last):
  File "/home/sergio/github/algotrader/Datagraber.py", line 117, in <module>
    [x.update(ohlcurl+x.tick,macdurl+x.tick,'5min') for x in symbolsdata]
  File "/home/sergio/github/algotrader/Datagraber.py", line 117, in <listcomp>
    [x.update(ohlcurl+x.tick,macdurl+x.tick,'5min') for x in symbolsdata]
  File "/home/sergio/github/algotrader/Datagraber.py", line 85, in update
    for keyo,keym in zip(list(ohlcdata.keys()),list(macddata.keys())):
UnboundLocalError: local variable 'macddata' referenced before assignment
dict_keys(['Meta Data', 'Time Series (5min)'])
1166
dict_keys(['Meta Data', 'Time Series (5min)'])
1166
dict_keys(['Meta Data', 'Time Series (5min)'])
1158
dict_keys(['Meta Data', 'Time Series (5min)'])
{'Note': 'Thank you for using Alpha Vantage! Our standard API call frequency is 5 calls per minute and 500 calls per day. Please visit https://www.alphavantage.co/premium/ if you would like to target a higher API call frequency.'}
1162
Traceback (most recent call last):
  File "/home/sergio/github/algotrader/Datagraber.py", line 117, in <module>
    [x.update(ohlcurl+x.tick,macdurl+x.tick,'5min') for x in symbolsdata]
  File "/home/sergio/github/algotrader/Datagraber.py", line 117, in <listcomp>
    [x.update(ohlcurl+x.tick,macdurl+x.tick,'5min') for x in symbolsdata]
  File "/home/sergio/github/algotrader/Datagraber.py", line 85, in update
    for keyo,keym in zip(list(ohlcdata.keys()),list(macddata.keys())):
UnboundLocalError: local variable 'macddata' referenced before assignment
dict_keys(['Meta Data', 'Time Series (5min)'])
{'Note': 'Thank you for using Alpha Vantage! Our standard API call frequency is 5 calls per minute and 500 calls per day. Please visit https://www.alphavantage.co/premium/ if you would like to target a higher API call frequency.'}
1166
Traceback (most recent call last):
  File "/home/sergio/github/algotrader/Datagraber.py", line 117, in <module>
    [x.update(ohlcurl+x.tick,macdurl+x.tick,'5min') for x in symbolsdata]
  File "/home/sergio/github/algotrader/Datagraber.py", line 117, in <listcomp>
    [x.update(ohlcurl+x.tick,macdurl+x.tick,'5min') for x in symbolsdata]
  File "/home/sergio/github/algotrader/Datagraber.py", line 85, in update
    for keyo,keym in zip(list(ohlcdata.keys()),list(macddata.keys())):
UnboundLocalError: local variable 'macddata' referenced before assignment
dict_keys(['Meta Data', 'Time Series (5min)'])
1166
dict_keys(['Meta Data', 'Time Series (5min)'])
1166
dict_keys(['Meta Data', 'Time Series (5min)'])
1158
dict_keys(['Meta Data', 'Time Series (5min)'])
1162
dict_keys(['Meta Data', 'Time Series (5min)'])
1158
dict_keys(['Meta Data', 'Time Series (5min)'])
1163
dict_keys(['Meta Data', 'Time Series (5min)'])
1166
dict_keys(['Meta Data', 'Time Series (5min)'])
14
dict_keys(['Meta Data', 'Time Series (5min)'])
{'Note': 'Thank you for using Alpha Vantage! Our standard API call frequency is 5 calls per minute and 500 calls per day. Please visit https://www.alphavantage.co/premium/ if you would like to target a higher API call frequency.'}
1166
Traceback (most recent call last):
  File "/home/sergio/github/algotrader/Datagraber.py", line 117, in <module>
    [x.update(ohlcurl+x.tick,macdurl+x.tick,'5min') for x in symbolsdata]
  File "/home/sergio/github/algotrader/Datagraber.py", line 117, in <listcomp>
    [x.update(ohlcurl+x.tick,macdurl+x.tick,'5min') for x in symbolsdata]
  File "/home/sergio/github/algotrader/Datagraber.py", line 85, in update
    for keyo,keym in zip(list(ohlcdata.keys()),list(macddata.keys())):
UnboundLocalError: local variable 'macddata' referenced before assignment
dict_keys(['Meta Data', 'Time Series (5min)'])
1166
dict_keys(['Meta Data', 'Time Series (5min)'])
1166
dict_keys(['Meta Data', 'Time Series (5min)'])
{'Note': 'Thank you for using Alpha Vantage! Our standard API call frequency is 5 calls per minute and 500 calls per day. Please visit https://www.alphavantage.co/premium/ if you would like to target a higher API call frequency.'}
1162
Traceback (most recent call last):
  File "/home/sergio/github/algotrader/Datagraber.py", line 117, in <module>
    [x.update(ohlcurl+x.tick,macdurl+x.tick,'5min') for x in symbolsdata]
  File "/home/sergio/github/algotrader/Datagraber.py", line 117, in <listcomp>
    [x.update(ohlcurl+x.tick,macdurl+x.tick,'5min') for x in symbolsdata]
  File "/home/sergio/github/algotrader/Datagraber.py", line 85, in update
    for keyo,keym in zip(list(ohlcdata.keys()),list(macddata.keys())):
UnboundLocalError: local variable 'macddata' referenced before assignment
dict_keys(['Meta Data', 'Time Series (5min)'])
{'Note': 'Thank you for using Alpha Vantage! Our standard API call frequency is 5 calls per minute and 500 calls per day. Please visit https://www.alphavantage.co/premium/ if you would like to target a higher API call frequency.'}
1166
Traceback (most recent call last):
  File "/home/sergio/github/algotrader/Datagraber.py", line 117, in <module>
    [x.update(ohlcurl+x.tick,macdurl+x.tick,'5min') for x in symbolsdata]
  File "/home/sergio/github/algotrader/Datagraber.py", line 117, in <listcomp>
    [x.update(ohlcurl+x.tick,macdurl+x.tick,'5min') for x in symbolsdata]
  File "/home/sergio/github/algotrader/Datagraber.py", line 85, in update
    for keyo,keym in zip(list(ohlcdata.keys()),list(macddata.keys())):
UnboundLocalError: local variable 'macddata' referenced before assignment
dict_keys(['Meta Data', 'Time Series (5min)'])
1166
dict_keys(['Meta Data', 'Time Series (5min)'])
1166
dict_keys(['Meta Data', 'Time Series (5min)'])
1162
dict_keys(['Meta Data', 'Time Series (5min)'])
1162
dict_keys(['Meta Data', 'Time Series (5min)'])
1162
dict_keys(['Meta Data', 'Time Series (5min)'])
1163
dict_keys(['Meta Data', 'Time Series (5min)'])
1166
dict_keys(['Meta Data', 'Time Series (5min)'])
14
dict_keys(['Meta Data', 'Time Series (5min)'])
1166
dict_keys(['Meta Data', 'Time Series (5min)'])
1166
dict_keys(['Meta Data', 'Time Series (5min)'])
1162
dict_keys(['Note'])
Traceback (most recent call last):
  File "/home/sergio/github/algotrader/Datagraber.py", line 117, in <module>
    [x.update(ohlcurl+x.tick,macdurl+x.tick,'5min') for x in symbolsdata]
  File "/home/sergio/github/algotrader/Datagraber.py", line 117, in <listcomp>
    [x.update(ohlcurl+x.tick,macdurl+x.tick,'5min') for x in symbolsdata]
  File "/home/sergio/github/algotrader/Datagraber.py", line 76, in update
    ohlcdata=ohlctmp['Time Series ('+interval+')']
KeyError: 'Time Series (5min)'
dict_keys(['Meta Data', 'Time Series (5min)'])
1166
dict_keys(['Note'])
Traceback (most recent call last):
  File "/home/sergio/github/algotrader/Datagraber.py", line 117, in <module>
    [x.update(ohlcurl+x.tick,macdurl+x.tick,'5min') for x in symbolsdata]
  File "/home/sergio/github/algotrader/Datagraber.py", line 117, in <listcomp>
    [x.update(ohlcurl+x.tick,macdurl+x.tick,'5min') for x in symbolsdata]
  File "/home/sergio/github/algotrader/Datagraber.py", line 76, in update
    ohlcdata=ohlctmp['Time Series ('+interval+')']
KeyError: 'Time Series (5min)'
dict_keys(['Meta Data', 'Time Series (5min)'])
1166
dict_keys(['Meta Data', 'Time Series (5min)'])
1166
dict_keys(['Meta Data', 'Time Series (5min)'])
1162
dict_keys(['Meta Data', 'Time Series (5min)'])
1158
dict_keys(['Meta Data', 'Time Series (5min)'])
1158
dict_keys(['Meta Data', 'Time Series (5min)'])
1163
dict_keys(['Meta Data', 'Time Series (5min)'])
1166
dict_keys(['Meta Data', 'Time Series (5min)'])
14
dict_keys(['Meta Data', 'Time Series (5min)'])
1164
dict_keys(['Meta Data', 'Time Series (5min)'])
1164
dict_keys(['Meta Data', 'Time Series (5min)'])
1159
dict_keys(['Meta Data', 'Time Series (5min)'])
1156
dict_keys(['Meta Data', 'Time Series (5min)'])
1160
dict_keys(['Meta Data', 'Time Series (5min)'])
1160
dict_keys(['Meta Data', 'Time Series (5min)'])
1164
dict_keys(['Meta Data', 'Time Series (5min)'])
15
dict_keys(['Meta Data', 'Time Series (5min)'])
1164
dict_keys(['Meta Data', 'Time Series (5min)'])
1164
dict_keys(['Meta Data', 'Time Series (5min)'])
1155
dict_keys(['Meta Data', 'Time Series (5min)'])
1160
dict_keys(['Meta Data', 'Time Series (5min)'])
1160
dict_keys(['Meta Data', 'Time Series (5min)'])
1160
dict_keys(['Meta Data', 'Time Series (5min)'])
1164
dict_keys(['Error Message'])
Traceback (most recent call last):
  File "/home/sergio/github/algotrader/Datagraber.py", line 117, in <module>
    [x.update(ohlcurl+x.tick,macdurl+x.tick,'5min') for x in symbolsdata]
  File "/home/sergio/github/algotrader/Datagraber.py", line 117, in <listcomp>
    [x.update(ohlcurl+x.tick,macdurl+x.tick,'5min') for x in symbolsdata]
  File "/home/sergio/github/algotrader/Datagraber.py", line 76, in update
    ohlcdata=ohlctmp['Time Series ('+interval+')']
KeyError: 'Time Series (5min)'
dict_keys(['Meta Data', 'Time Series (5min)'])
1164
dict_keys(['Meta Data', 'Time Series (5min)'])
1164
dict_keys(['Meta Data', 'Time Series (5min)'])
1159
dict_keys(['Meta Data', 'Time Series (5min)'])
1156
dict_keys(['Meta Data', 'Time Series (5min)'])
1160
dict_keys(['Meta Data', 'Time Series (5min)'])
1160
dict_keys(['Meta Data', 'Time Series (5min)'])
1164
dict_keys(['Error Message'])
Traceback (most recent call last):
  File "/home/sergio/github/algotrader/Datagraber.py", line 117, in <module>
    [x.update(ohlcurl+x.tick,macdurl+x.tick,'5min') for x in symbolsdata]
  File "/home/sergio/github/algotrader/Datagraber.py", line 117, in <listcomp>
    [x.update(ohlcurl+x.tick,macdurl+x.tick,'5min') for x in symbolsdata]
  File "/home/sergio/github/algotrader/Datagraber.py", line 76, in update
    ohlcdata=ohlctmp['Time Series ('+interval+')']
KeyError: 'Time Series (5min)'
dict_keys(['Meta Data', 'Time Series (5min)'])
1164
dict_keys(['Meta Data', 'Time Series (5min)'])
1164
dict_keys(['Meta Data', 'Time Series (5min)'])
1159
dict_keys(['Meta Data', 'Time Series (5min)'])
1160
dict_keys(['Meta Data', 'Time Series (5min)'])
1160
dict_keys(['Meta Data', 'Time Series (5min)'])
1160
dict_keys(['Meta Data', 'Time Series (5min)'])
1164
dict_keys(['Error Message'])
Traceback (most recent call last):
  File "/home/sergio/github/algotrader/Datagraber.py", line 117, in <module>
    [x.update(ohlcurl+x.tick,macdurl+x.tick,'5min') for x in symbolsdata]
  File "/home/sergio/github/algotrader/Datagraber.py", line 117, in <listcomp>
    [x.update(ohlcurl+x.tick,macdurl+x.tick,'5min') for x in symbolsdata]
  File "/home/sergio/github/algotrader/Datagraber.py", line 76, in update
    ohlcdata=ohlctmp['Time Series ('+interval+')']
KeyError: 'Time Series (5min)'
dict_keys(['Meta Data', 'Time Series (5min)'])
1164
dict_keys(['Meta Data', 'Time Series (5min)'])
1164
dict_keys(['Meta Data', 'Time Series (5min)'])
1159
dict_keys(['Meta Data', 'Time Series (5min)'])
1160
dict_keys(['Meta Data', 'Time Series (5min)'])
1156
dict_keys(['Meta Data', 'Time Series (5min)'])
1160
dict_keys(['Meta Data', 'Time Series (5min)'])
1164
dict_keys(['Error Message'])
Traceback (most recent call last):
  File "/home/sergio/github/algotrader/Datagraber.py", line 117, in <module>
    [x.update(ohlcurl+x.tick,macdurl+x.tick,'5min') for x in symbolsdata]
  File "/home/sergio/github/algotrader/Datagraber.py", line 117, in <listcomp>
    [x.update(ohlcurl+x.tick,macdurl+x.tick,'5min') for x in symbolsdata]
  File "/home/sergio/github/algotrader/Datagraber.py", line 76, in update
    ohlcdata=ohlctmp['Time Series ('+interval+')']
KeyError: 'Time Series (5min)'
dict_keys(['Meta Data', 'Time Series (5min)'])
1164
dict_keys(['Meta Data', 'Time Series (5min)'])
1164
dict_keys(['Meta Data', 'Time Series (5min)'])
1155
dict_keys(['Meta Data', 'Time Series (5min)'])
1160
dict_keys(['Meta Data', 'Time Series (5min)'])
1156
dict_keys(['Meta Data', 'Time Series (5min)'])
1160
dict_keys(['Meta Data', 'Time Series (5min)'])
1164
dict_keys(['Meta Data', 'Time Series (5min)'])
15
dict_keys(['Meta Data', 'Time Series (5min)'])
1164
dict_keys(['Meta Data', 'Time Series (5min)'])
1164
dict_keys(['Meta Data', 'Time Series (5min)'])
1159
dict_keys(['Note'])
Traceback (most recent call last):
  File "/home/sergio/github/algotrader/Datagraber.py", line 117, in <module>
    [x.update(ohlcurl+x.tick,macdurl+x.tick,'5min') for x in symbolsdata]
  File "/home/sergio/github/algotrader/Datagraber.py", line 117, in <listcomp>
    [x.update(ohlcurl+x.tick,macdurl+x.tick,'5min') for x in symbolsdata]
  File "/home/sergio/github/algotrader/Datagraber.py", line 76, in update
    ohlcdata=ohlctmp['Time Series ('+interval+')']
KeyError: 'Time Series (5min)'
dict_keys(['Meta Data', 'Time Series (5min)'])
1164
dict_keys(['Meta Data', 'Time Series (5min)'])
1164
dict_keys(['Note'])
Traceback (most recent call last):
  File "/home/sergio/github/algotrader/Datagraber.py", line 117, in <module>
    [x.update(ohlcurl+x.tick,macdurl+x.tick,'5min') for x in symbolsdata]
  File "/home/sergio/github/algotrader/Datagraber.py", line 117, in <listcomp>
    [x.update(ohlcurl+x.tick,macdurl+x.tick,'5min') for x in symbolsdata]
  File "/home/sergio/github/algotrader/Datagraber.py", line 76, in update
    ohlcdata=ohlctmp['Time Series ('+interval+')']
KeyError: 'Time Series (5min)'
dict_keys(['Meta Data', 'Time Series (5min)'])
1090
dict_keys(['Meta Data', 'Time Series (5min)'])
1090
dict_keys(['Meta Data', 'Time Series (5min)'])
1085
dict_keys(['Meta Data', 'Time Series (5min)'])
1082
dict_keys(['Meta Data', 'Time Series (5min)'])
1087
dict_keys(['Meta Data', 'Time Series (5min)'])
1087
dict_keys(['Meta Data', 'Time Series (5min)'])
1091
dict_keys(['Meta Data', 'Time Series (5min)'])
14
dict_keys(['Meta Data', 'Time Series (5min)'])
1124
dict_keys(['Note'])
Traceback (most recent call last):
  File "/home/sergio/github/algotrader/Datagraber.py", line 117, in <module>
    [x.update(ohlcurl+x.tick,macdurl+x.tick,'5min') for x in symbolsdata]
  File "/home/sergio/github/algotrader/Datagraber.py", line 117, in <listcomp>
    [x.update(ohlcurl+x.tick,macdurl+x.tick,'5min') for x in symbolsdata]
  File "/home/sergio/github/algotrader/Datagraber.py", line 76, in update
    ohlcdata=ohlctmp['Time Series ('+interval+')']
KeyError: 'Time Series (5min)'
dict_keys(['Meta Data', 'Time Series (5min)'])
1124
dict_keys(['Meta Data', 'Time Series (5min)'])
1121
dict_keys(['Meta Data', 'Time Series (5min)'])
1119
dict_keys(['Note'])
Traceback (most recent call last):
  File "/home/sergio/github/algotrader/Datagraber.py", line 117, in <module>
    [x.update(ohlcurl+x.tick,macdurl+x.tick,'5min') for x in symbolsdata]
  File "/home/sergio/github/algotrader/Datagraber.py", line 117, in <listcomp>
    [x.update(ohlcurl+x.tick,macdurl+x.tick,'5min') for x in symbolsdata]
  File "/home/sergio/github/algotrader/Datagraber.py", line 76, in update
    ohlcdata=ohlctmp['Time Series ('+interval+')']
KeyError: 'Time Series (5min)'
dict_keys(['Note'])
Traceback (most recent call last):
  File "/home/sergio/github/algotrader/Datagraber.py", line 117, in <module>
    [x.update(ohlcurl+x.tick,macdurl+x.tick,'5min') for x in symbolsdata]
  File "/home/sergio/github/algotrader/Datagraber.py", line 117, in <listcomp>
    [x.update(ohlcurl+x.tick,macdurl+x.tick,'5min') for x in symbolsdata]
  File "/home/sergio/github/algotrader/Datagraber.py", line 76, in update
    ohlcdata=ohlctmp['Time Series ('+interval+')']
KeyError: 'Time Series (5min)'
dict_keys(['Meta Data', 'Time Series (5min)'])
1128
dict_keys(['Meta Data', 'Time Series (5min)'])
{'Note': 'Thank you for using Alpha Vantage! Our standard API call frequency is 5 calls per minute and 500 calls per day. Please visit https://www.alphavantage.co/premium/ if you would like to target a higher API call frequency.'}
1086
Traceback (most recent call last):
  File "/home/sergio/github/algotrader/Datagraber.py", line 117, in <module>
    [x.update(ohlcurl+x.tick,macdurl+x.tick,'5min') for x in symbolsdata]
  File "/home/sergio/github/algotrader/Datagraber.py", line 117, in <listcomp>
    [x.update(ohlcurl+x.tick,macdurl+x.tick,'5min') for x in symbolsdata]
  File "/home/sergio/github/algotrader/Datagraber.py", line 85, in update
    for keyo,keym in zip(list(ohlcdata.keys()),list(macddata.keys())):
UnboundLocalError: local variable 'macddata' referenced before assignment
dict_keys(['Meta Data', 'Time Series (5min)'])
1127
dict_keys(['Meta Data', 'Time Series (5min)'])
1128
dict_keys(['Meta Data', 'Time Series (5min)'])
1123
dict_keys(['Meta Data', 'Time Series (5min)'])
1120
dict_keys(['Meta Data', 'Time Series (5min)'])
1124
dict_keys(['Meta Data', 'Time Series (5min)'])
1124
dict_keys(['Note'])
Traceback (most recent call last):
  File "/home/sergio/github/algotrader/Datagraber.py", line 117, in <module>
    [x.update(ohlcurl+x.tick,macdurl+x.tick,'5min') for x in symbolsdata]
  File "/home/sergio/github/algotrader/Datagraber.py", line 117, in <listcomp>
    [x.update(ohlcurl+x.tick,macdurl+x.tick,'5min') for x in symbolsdata]
  File "/home/sergio/github/algotrader/Datagraber.py", line 76, in update
    ohlcdata=ohlctmp['Time Series ('+interval+')']
KeyError: 'Time Series (5min)'
dict_keys(['Meta Data', 'Time Series (5min)'])
1129
dict_keys(['Meta Data', 'Time Series (5min)'])
1130
dict_keys(['Meta Data', 'Time Series (5min)'])
1121
dict_keys(['Meta Data', 'Time Series (5min)'])
1126
dict_keys(['Meta Data', 'Time Series (5min)'])
1122
dict_keys(['Meta Data', 'Time Series (5min)'])
1124
dict_keys(['Meta Data', 'Time Series (5min)'])
1130
dict_keys(['Meta Data', 'Time Series (5min)'])
14
dict_keys(['Meta Data', 'Time Series (5min)'])
1135
dict_keys(['Meta Data', 'Time Series (5min)'])
1135
dict_keys(['Meta Data', 'Time Series (5min)'])
1126
dict_keys(['Meta Data', 'Time Series (5min)'])
1131
dict_keys(['Meta Data', 'Time Series (5min)'])
1131
dict_keys(['Meta Data', 'Time Series (5min)'])
1131
dict_keys(['Meta Data', 'Time Series (5min)'])
1136
dict_keys(['Meta Data', 'Time Series (5min)'])
14
dict_keys(['Meta Data', 'Time Series (5min)'])
1164
dict_keys(['Meta Data', 'Time Series (5min)'])
1164
dict_keys(['Note'])
Traceback (most recent call last):
  File "/home/sergio/github/algotrader/Datagraber.py", line 117, in <module>
    [x.update(ohlcurl+x.tick,macdurl+x.tick,'5min') for x in symbolsdata]
  File "/home/sergio/github/algotrader/Datagraber.py", line 117, in <listcomp>
    [x.update(ohlcurl+x.tick,macdurl+x.tick,'5min') for x in symbolsdata]
  File "/home/sergio/github/algotrader/Datagraber.py", line 76, in update
    ohlcdata=ohlctmp['Time Series ('+interval+')']
KeyError: 'Time Series (5min)'
dict_keys(['Meta Data', 'Time Series (5min)'])
1164
dict_keys(['Meta Data', 'Time Series (5min)'])
1164
dict_keys(['Note'])
Traceback (most recent call last):
  File "/home/sergio/github/algotrader/Datagraber.py", line 117, in <module>
    [x.update(ohlcurl+x.tick,macdurl+x.tick,'5min') for x in symbolsdata]
  File "/home/sergio/github/algotrader/Datagraber.py", line 117, in <listcomp>
    [x.update(ohlcurl+x.tick,macdurl+x.tick,'5min') for x in symbolsdata]
  File "/home/sergio/github/algotrader/Datagraber.py", line 76, in update
    ohlcdata=ohlctmp['Time Series ('+interval+')']
KeyError: 'Time Series (5min)'
dict_keys(['Meta Data', 'Time Series (5min)'])
1164
dict_keys(['Meta Data', 'Time Series (5min)'])
1164
dict_keys(['Meta Data', 'Time Series (5min)'])
1159
dict_keys(['Meta Data', 'Time Series (5min)'])
1160
dict_keys(['Meta Data', 'Time Series (5min)'])
1160
dict_keys(['Meta Data', 'Time Series (5min)'])
1160
dict_keys(['Meta Data', 'Time Series (5min)'])
1164
dict_keys(['Error Message'])
Traceback (most recent call last):
  File "/home/sergio/github/algotrader/Datagraber.py", line 117, in <module>
    [x.update(ohlcurl+x.tick,macdurl+x.tick,'5min') for x in symbolsdata]
  File "/home/sergio/github/algotrader/Datagraber.py", line 117, in <listcomp>
    [x.update(ohlcurl+x.tick,macdurl+x.tick,'5min') for x in symbolsdata]
  File "/home/sergio/github/algotrader/Datagraber.py", line 76, in update
    ohlcdata=ohlctmp['Time Series ('+interval+')']
KeyError: 'Time Series (5min)'
dict_keys(['Meta Data', 'Time Series (5min)'])
1162
dict_keys(['Meta Data', 'Time Series (5min)'])
1162
dict_keys(['Meta Data', 'Time Series (5min)'])
1157
dict_keys(['Meta Data', 'Time Series (5min)'])
1158
dict_keys(['Meta Data', 'Time Series (5min)'])
1158
dict_keys(['Meta Data', 'Time Series (5min)'])
1158
dict_keys(['Meta Data', 'Time Series (5min)'])
1162
dict_keys(['Meta Data', 'Time Series (5min)'])
15
dict_keys(['Meta Data', 'Time Series (5min)'])
1162
dict_keys(['Meta Data', 'Time Series (5min)'])
1162
dict_keys(['Meta Data', 'Time Series (5min)'])
1157
dict_keys(['Meta Data', 'Time Series (5min)'])
1158
dict_keys(['Meta Data', 'Time Series (5min)'])
1158
dict_keys(['Meta Data', 'Time Series (5min)'])
1158
dict_keys(['Meta Data', 'Time Series (5min)'])
1162
dict_keys(['Meta Data', 'Time Series (5min)'])
15
dict_keys(['Meta Data', 'Time Series (5min)'])
1162
dict_keys(['Meta Data', 'Time Series (5min)'])
1162
dict_keys(['Meta Data', 'Time Series (5min)'])
1153
dict_keys(['Meta Data', 'Time Series (5min)'])
1158
dict_keys(['Meta Data', 'Time Series (5min)'])
1158
dict_keys(['Meta Data', 'Time Series (5min)'])
1158
dict_keys(['Meta Data', 'Time Series (5min)'])
1162
dict_keys(['Error Message'])
Traceback (most recent call last):
  File "/home/sergio/github/algotrader/Datagraber.py", line 117, in <module>
    [x.update(ohlcurl+x.tick,macdurl+x.tick,'5min') for x in symbolsdata]
  File "/home/sergio/github/algotrader/Datagraber.py", line 117, in <listcomp>
    [x.update(ohlcurl+x.tick,macdurl+x.tick,'5min') for x in symbolsdata]
  File "/home/sergio/github/algotrader/Datagraber.py", line 76, in update
    ohlcdata=ohlctmp['Time Series ('+interval+')']
KeyError: 'Time Series (5min)'
dict_keys(['Meta Data', 'Time Series (5min)'])
1093
dict_keys(['Meta Data', 'Time Series (5min)'])
1093
dict_keys(['Meta Data', 'Time Series (5min)'])
1088
dict_keys(['Meta Data', 'Time Series (5min)'])
1085
dict_keys(['Meta Data', 'Time Series (5min)'])
1085
dict_keys(['Meta Data', 'Time Series (5min)'])
1089
dict_keys(['Meta Data', 'Time Series (5min)'])
1093
dict_keys(['Meta Data', 'Time Series (5min)'])
14
dict_keys(['Meta Data', 'Time Series (5min)'])
1162
dict_keys(['Meta Data', 'Time Series (5min)'])
1162
dict_keys(['Meta Data', 'Time Series (5min)'])
1156
dict_keys(['Meta Data', 'Time Series (5min)'])
1160
dict_keys(['Meta Data', 'Time Series (5min)'])
1157
dict_keys(['Meta Data', 'Time Series (5min)'])
1158
dict_keys(['Meta Data', 'Time Series (5min)'])
1162
dict_keys(['Meta Data', 'Time Series (5min)'])
15
dict_keys(['Meta Data', 'Time Series (5min)'])
1162
dict_keys(['Meta Data', 'Time Series (5min)'])
1162
dict_keys(['Meta Data', 'Time Series (5min)'])
1159
dict_keys(['Meta Data', 'Time Series (5min)'])
1160
dict_keys(['Meta Data', 'Time Series (5min)'])
1160
dict_keys(['Meta Data', 'Time Series (5min)'])
1158
dict_keys(['Meta Data', 'Time Series (5min)'])
1162
dict_keys(['Error Message'])
Traceback (most recent call last):
  File "/home/sergio/github/algotrader/Datagraber.py", line 117, in <module>
    [x.update(ohlcurl+x.tick,macdurl+x.tick,'5min') for x in symbolsdata]
  File "/home/sergio/github/algotrader/Datagraber.py", line 117, in <listcomp>
    [x.update(ohlcurl+x.tick,macdurl+x.tick,'5min') for x in symbolsdata]
  File "/home/sergio/github/algotrader/Datagraber.py", line 76, in update
    ohlcdata=ohlctmp['Time Series ('+interval+')']
KeyError: 'Time Series (5min)'
dict_keys(['Meta Data', 'Time Series (5min)'])
1114
dict_keys(['Meta Data', 'Time Series (5min)'])
1112
dict_keys(['Meta Data', 'Time Series (5min)'])
1111
dict_keys(['Meta Data', 'Time Series (5min)'])
1112
dict_keys(['Meta Data', 'Time Series (5min)'])
1112
dict_keys(['Meta Data', 'Time Series (5min)'])
1110
dict_keys(['Meta Data', 'Time Series (5min)'])
1115
dict_keys(['Meta Data', 'Time Series (5min)'])
14
